Workbook

Sheet 안내
B2: 인력공급 계획/실적표 사용법
B3: Hướng dẫn sử dụng — Bảng kế hoạch & thực tế cung ứng lao động
B5: ① 고객사 | C5: 고객사 코드·이름·단가·차량지원 여부(Y/N)를 한 번만 등록합니다. 지원형태가 '자사 차량 운행'이면 자사차량비(대·일)를 입력하세요.
B6: ② 일일계획실적 | C6: 매일 날짜 / 고객사코드(드롭다운) / 직무 / 교대 / 계획인원 / 실적인원을 입력합니다. 자사 차량을 운행했다면 대수를 입력하세요.
C7: 고객사명·달성률·결원·차량지원·매출·인건비·이익은 자동 계산됩니다. 달성률 90% 미만, '차량 미배정'은 빨간색으로 표시됩니다.
B8: ③ 월간요약 | C8: C3 기준월(예: 2026-10-01)만 바꾸면 고객사별 연인원·달성률·매출·이익과 일자별 추이 차트가 갱신됩니다.
B9: ④ 목록 | C9: 직무·교대·지원형태 드롭다운 항목을 추가/수정할 수 있습니다.
B10: 예시 데이터 | C10: 고객사 C001~C004와 2026년 9월 일일 데이터는 예시입니다. 실제 사용 전 노란 칸의 예시 값을 지우세요 (수식 칸은 지우지 마세요).
B11: 제안서 연결 | C11: 월간요약의 달성률·연인원을 제안서(labor-kit/proposal/data/company.json의 performance)에 옮기면 제안서 실적 차트에 반영됩니다.
B13: 색상 범례
C14: 입력 칸 — 직접 입력/수정
C15: 자동 계산 — 수식이 들어 있으니 지우지 마세요
C16: 합계

Sheet 고객사
A1: 고객사 마스터 / Danh sách khách hàng
A2: 노란 칸 입력. 코드는 중복 없이 입력하세요 (일일계획실적에서 코드로 연결됩니다).
A4: 고객사코드 Mã KH | B4: 고객사명 Tên khách hàng | C4: 지역(성/시) Tỉnh/TP | D4: 업종 Ngành | E4: 담당자 Người phụ trách | F4: 연락처 SĐT | G4: 고객사 차량지원 (Y/N) | H4: 지원형태 Hình thức | I4: 픽업지점 Điểm đón | J4: 청구단가 (VND/인·일) | K4: 지급임금 (VND/인·일) | L4: 자사차량비 (VND/대·일) | M4: 계약시작 Bắt đầu | N4: 계약종료 Kết thúc | O4: 비고 Ghi chú
A5: C001 | B5: 예시) 한빛전자 비나 | C5: 박닌 | D5: 전자부품 | E5: Nguyễn Văn A | F5: 0912-000-001 | G5: Y | H5: 고객사 셔틀버스 | I5: 박닌 버스터미널 | J5: 420000 | K5: 330000 | L5: 0 | M5: 46023 | N5: 46387 | O5: 야간 할증 별도
A6: C002 | B6: 예시) 대성섬유 VN | C6: 동나이 | D6: 봉제 | E6: Trần Thị B | F6: 0912-000-002 | G6: N | H6: 자사 차량 운행 | I6: 비엔호아 시장 | J6: 380000 | K6: 300000 | L6: 1200000 | M6: 46082 | N6: 46446 | O6: 29인승 버스 1대
A7: C003 | B7: 예시) 그린물류 하노이 | C7: 하노이 | D7: 물류 | E7: Lê Văn C | F7: 0912-000-003 | G7: N | H7: 미지원(개별 출퇴근) | I7: - | J7: 400000 | K7: 315000 | L7: 0 | M7: 46174 | N7: 46356
A8: C004 | B8: 예시) 미래식품 빈즈엉 | C8: 빈즈엉 | D8: 식품 | E8: Phạm Thị D | F8: 0912-000-004 | G8: Y | H8: 고객사 교통비 지급 | I8: - | J8: 390000 | K8: 305000 | L8: 0 | M8: 46143 | N8: 46507 | O8: 교통비 1일 20,000 고객사 지급

Sheet 일일계획실적
A1: 일일 계획 / 실적 — Kế hoạch & Thực tế hằng ngày
A2: 노란 칸(날짜·고객사코드·직무·교대·계획·실적·자사차량·비고)만 입력하면 회색 칸은 자동 계산됩니다.
A4: 날짜 Ngày | B4: 고객사코드 Mã KH | C4: 고객사명 Tên KH | D4: 직무 Công việc | E4: 교대 Ca | F4: 계획인원 Kế hoạch | G4: 실적인원 Thực tế | H4: 달성률 Tỷ lệ đạt | I4: 결원 Thiếu | J4: 고객사 차량지원 KH hỗ trợ xe | K4: 자사 차량운행(대) Xe công ty | L4: 차량비용(VND) Chi phí xe | M4: 차량확인 Kiểm tra xe | N4: 청구단가 Đơn giá thu | O4: 매출(VND) Doanh thu | P4: 지급임금 Đơn giá lương | Q4: 인건비(VND) Chi phí lương | R4: 이익(VND) Lợi nhuận | S4: 이익률 Tỷ suất | T4: 비고 Ghi chú | U4: 보조(운영일)
A5: 46266 | B5: C001 | C5: =IF($B5="","",IFERROR(INDEX(고객사!$B$5:$B$104,MATCH($B5,고객사!$A$5:$A$104,0)),"코드 확인")) -> 예시) 한빛전자 비나 | D5: 생산 라인 | E5: 주간 | F5: 40 | G5: 38 | H5: =IF(OR($B5="",F5=0),"",G5/F5) -> 0.95 | I5: =IF($B5="","",MAX(F5-G5,0)) -> 2 | J5: =IF($B5="","",IFERROR(INDEX(고객사!$G$5:$G$104,MATCH($B5,고객사!$A$5:$A$104,0)),"")) -> Y | K5: 0 | L5: =IF($B5="","",K5*IFERROR(INDEX(고객사!$L$5:$L$104,MATCH($B5,고객사!$A$5:$A$104,0)),0)) -> 0 | M5: =IF($B5="","",IF(AND(J5="N",G5>0,K5=0,IFERROR(INDEX(고객사!$H$5:$H$104,MATCH($B5,고객사!$A$5:$A$104,0)),"")="자사 차량 운행"),"차량 미배정","")) | N5: =IF($B5="","",IFERROR(INDEX(고객사!$J$5:$J$104,MATCH($B5,고객사!$A$5:$A$104,0)),0)) -> 420000 | O5: =IF($B5="","",G5*N5) -> 15960000 | P5: =IF($B5="","",IFERROR(INDEX(고객사!$K$5:$K$104,MATCH($B5,고객사!$A$5:$A$104,0)),0)) -> 330000 | Q5: =IF($B5="","",G5*P5) -> 12540000 | R5: =IF($B5="","",O5-Q5-L5) -> 3420000 | S5: =IF(OR($B5="",N(O5)=0),"",R5/O5) -> 0.21428571 | T5: 예시 데이터 — 삭제 후 사용 | U5: =IF(OR($B5="",$A5=""),0,IF(COUNTIFS($A$5:$A5,$A5,$B$5:$B5,$B5)=1,1,0)) -> 1
A6: 46266 | B6: C001 | C6: =IF($B6="","",IFERROR(INDEX(고객사!$B$5:$B$104,MATCH($B6,고객사!$A$5:$A$104,0)),"코드 확인")) -> 예시) 한빛전자 비나 | D6: 검사(QC) | E6: 야간 | F6: 12 | G6: 12 | H6: =IF(OR($B6="",F6=0),"",G6/F6) -> 1 | I6: =IF($B6="","",MAX(F6-G6,0)) -> 0 | J6: =IF($B6="","",IFERROR(INDEX(고객사!$G$5:$G$104,MATCH($B6,고객사!$A$5:$A$104,0)),"")) -> Y | K6: 0 | L6: =IF($B6="","",K6*IFERROR(INDEX(고객사!$L$5:$L$104,MATCH($B6,고객사!$A$5:$A$104,0)),0)) -> 0 | M6: =IF($B6="","",IF(AND(J6="N",G6>0,K6=0,IFERROR(INDEX(고객사!$H$5:$H$104,MATCH($B6,고객사!$A$5:$A$104,0)),"")="자사 차량 운행"),"차량 미배정","")) | N6: =IF($B6="","",IFERROR(INDEX(고객사!$J$5:$J$104,MATCH($B6,고객사!$A$5:$A$104,0)),0)) -> 420000 | O6: =IF($B6="","",G6*N6) -> 5040000 | P6: =IF($B6="","",IFERROR(INDEX(고객사!$K$5:$K$104,MATCH($B6,고객사!$A$5:$A$104,0)),0)) -> 330000 | Q6: =IF($B6="","",G6*P6) -> 3960000 | R6: =IF($B6="","",O6-Q6-L6) -> 1080000 | S6: =IF(OR($B6="",N(O6)=0),"",R6/O6) -> 0.21428571 | U6: =IF(OR($B6="",$A6=""),0,IF(COUNTIFS($A$5:$A6,$A6,$B$5:$B6,$B6)=1,1,0)) -> 0
A7: 46266 | B7: C002 | C7: =IF($B7="","",IFERROR(INDEX(고객사!$B$5:$B$104,MATCH($B7,고객사!$A$5:$A$104,0)),"코드 확인")) -> 예시) 대성섬유 VN | D7: 봉제 | E7: 주간 | F7: 30 | G7: 27 | H7: =IF(OR($B7="",F7=0),"",G7/F7) -> 0.9 | I7: =IF($B7="","",MAX(F7-G7,0)) -> 3 | J7: =IF($B7="","",IFERROR(INDEX(고객사!$G$5:$G$104,MATCH($B7,고객사!$A$5:$A$104,0)),"")) -> N | K7: 1 | L7: =IF($B7="","",K7*IFERROR(INDEX(고객사!$L$5:$L$104,MATCH($B7,고객사!$A$5:$A$104,0)),0)) -> 1200000 | M7: =IF($B7="","",IF(AND(J7="N",G7>0,K7=0,IFERROR(INDEX(고객사!$H$5:$H$104,MATCH($B7,고객사!$A$5:$A$104,0)),"")="자사 차량 운행"),"차량 미배정","")) | N7: =IF($B7="","",IFERROR(INDEX(고객사!$J$5:$J$104,MATCH($B7,고객사!$A$5:$A$104,0)),0)) -> 380000 | O7: =IF($B7="","",G7*N7) -> 10260000 | P7: =IF($B7="","",IFERROR(INDEX(고객사!$K$5:$K$104,MATCH($B7,고객사!$A$5:$A$104,0)),0)) -> 300000 | Q7: =IF($B7="","",G7*P7) -> 8100000 | R7: =IF($B7="","",O7-Q7-L7) -> 960000 | S7: =IF(OR($B7="",N(O7)=0),"",R7/O7) -> 0.093567251 | U7: =IF(OR($B7="",$A7=""),0,IF(COUNTIFS($A$5:$A7,$A7,$B$5:$B7,$B7)=1,1,0)) -> 1
A8: 46266 | B8: C003 | C8: =IF($B8="","",IFERROR(INDEX(고객사!$B$5:$B$104,MATCH($B8,고객사!$A$5:$A$104,0)),"코드 확인")) -> 예시) 그린물류 하노이 | D8: 물류·상하차 | E8: 주간 | F8: 18 | G8: 18 | H8: =IF(OR($B8="",F8=0),"",G8/F8) -> 1 | I8: =IF($B8="","",MAX(F8-G8,0)) -> 0 | J8: =IF($B8="","",IFERROR(INDEX(고객사!$G$5:$G$104,MATCH($B8,고객사!$A$5:$A$104,0)),"")) -> N | K8: 0 | L8: =IF($B8="","",K8*IFERROR(INDEX(고객사!$L$5:$L$104,MATCH($B8,고객사!$A$5:$A$104,0)),0)) -> 0 | M8: =IF($B8="","",IF(AND(J8="N",G8>0,K8=0,IFERROR(INDEX(고객사!$H$5:$H$104,MATCH($B8,고객사!$A$5:$A$104,0)),"")="자사 차량 운행"),"차량 미배정","")) | N8: =IF($B8="","",IFERROR(INDEX(고객사!$J$5:$J$104,MATCH($B8,고객사!$A$5:$A$104,0)),0)) -> 400000 | O8: =IF($B8="","",G8*N8) -> 7200000 | P8: =IF($B8="","",IFERROR(INDEX(고객사!$K$5:$K$104,MATCH($B8,고객사!$A$5:$A$104,0)),0)) -> 315000 | Q8: =IF($B8="","",G8*P8) -> 5670000 | R8: =IF($B8="","",O8-Q8-L8) -> 1530000 | S8: =IF(OR($B8="",N(O8)=0),"",R8/O8) -> 0.2125 | U8: =IF(OR($B8="",$A8=""),0,IF(COUNTIFS($A$5:$A8,$A8,$B$5:$B8,$B8)=1,1,0)) -> 1
A9: 46266 | B9: C004 | C9: =IF($B9="","",IFERROR(INDEX(고객사!$B$5:$B$104,MATCH($B9,고객사!$A$5:$A$104,0)),"코드 확인")) -> 예시) 미래식품 빈즈엉 | D9: 포장 | E9: 2교대 | F9: 22 | G9: 22 | H9: =IF(OR($B9="",F9=0),"",G9/F9) -> 1 | I9: =IF($B9="","",MAX(F9-G9,0)) -> 0 | J9: =IF($B9="","",IFERROR(INDEX(고객사!$G$5:$G$104,MATCH($B9,고객사!$A$5:$A$104,0)),"")) -> Y | K9: 0 | L9: =IF($B9="","",K9*IFERROR(INDEX(고객사!$L$5:$L$104,MATCH($B9,고객사!$A$5:$A$104,0)),0)) -> 0 | M9: =IF($B9="","",IF(AND(J9="N",G9>0,K9=0,IFERROR(INDEX(고객사!$H$5:$H$104,MATCH($B9,고객사!$A$5:$A$104,0)),"")="자사 차량 운행"),"차량 미배정","")) | N9: =IF($B9="","",IFERROR(INDEX(고객사!$J$5:$J$104,MATCH($B9,고객사!$A$5:$A$104,0)),0)) -> 390000 | O9: =IF($B9="","",G9*N9) -> 8580000 | P9: =IF($B9="","",IFERROR(INDEX(고객사!$K$5:$K$104,MATCH($B9,고객사!$A$5:$A$104,0)),0)) -> 305000 | Q9: =IF($B9="","",G9*P9) -> 6710000 | R9: =IF($B9="","",O9-Q9-L9) -> 1870000 | S9: =IF(OR($B9="",N(O9)=0),"",R9/O9) -> 0.21794872 | U9: =IF(OR($B9="",$A9=""),0,IF(COUNTIFS($A$5:$A9,$A9,$B$5:$B9,$B9)=1,1,0)) -> 1
A10: 46267 | B10: C001 | C10: =IF($B10="","",IFERROR(INDEX(고객사!$B$5:$B$104,MATCH($B10,고객사!$A$5:$A$104,0)),"코드 확인")) -> 예시) 한빛전자 비나 | D10: 생산 라인 | E10: 주간 | F10: 40 | G10: 40 | H10: =IF(OR($B10="",F10=0),"",G10/F10) -> 1 | I10: =IF($B10="","",MAX(F10-G10,0)) -> 0 | J10: =IF($B10="","",IFERROR(INDEX(고객사!$G$5:$G$104,MATCH($B10,고객사!$A$5:$A$104,0)),"")) -> Y | K10: 0 | L10: =IF($B10="","",K10*IFERROR(INDEX(고객사!$L$5:$L$104,MATCH($B10,고객사!$A$5:$A$104,0)),0)) -> 0 | M10: =IF($B10="","",IF(AND(J10="N",G10>0,K10=0,IFERROR(INDEX(고객사!$H$5:$H$104,MATCH($B10,고객사!$A$5:$A$104,0)),"")="자사 차량 운행"),"차량 미배정","")) | N10: =IF($B10="","",IFERROR(INDEX(고객사!$J$5:$J$104,MATCH($B10,고객사!$A$5:$A$104,0)),0)) -> 420000 | O10: =IF($B10="","",G10*N10) -> 16800000 | P10: =IF($B10="","",IFERROR(INDEX(고객사!$K$5:$K$104,MATCH($B10,고객사!$A$5:$A$104,0)),0)) -> 330000 | Q10: =IF($B10="","",G10*P10) -> 13200000 | R10: =IF($B10="","",O10-Q10-L10) -> 3600000 | S10: =IF(OR($B10="",N(O10)=0),"",R10/O10) -> 0.21428571 | U10: =IF(OR($B10="",$A10=""),0,IF(COUNTIFS($A$5:$A10,$A10,$B$5:$B10,$B10)=1,1,0)) -> 1
A11: 46267 | B11: C001 | C11: =IF($B11="","",IFERROR(INDEX(고객사!$B$5:$B$104,MATCH($B11,고객사!$A$5:$A$104,0)),"코드 확인")) -> 예시) 한빛전자 비나 | D11: 검사(QC) | E11: 야간 | F11: 12 | G11: 10 | H11: =IF(OR($B11="",F11=0),"",G11/F11) -> 0.83333333 | I11: =IF($B11="","",MAX(F11-G11,0)) -> 2 | J11: =IF($B11="","",IFERROR(INDEX(고객사!$G$5:$G$104,MATCH($B11,고객사!$A$5:$A$104,0)),"")) -> Y | K11: 0 | L11: =IF($B11="","",K11*IFERROR(INDEX(고객사!$L$5:$L$104,MATCH($B11,고객사!$A$5:$A$104,0)),0)) -> 0 | M11: =IF($B11="","",IF(AND(J11="N",G11>0,K11=0,IFERROR(INDEX(고객사!$H$5:$H$104,MATCH($B11,고객사!$A$5:$A$104,0)),"")="자사 차량 운행"),"차량 미배정","")) | N11: =IF($B11="","",IFERROR(INDEX(고객사!$J$5:$J$104,MATCH($B11,고객사!$A$5:$A$104,0)),0)) -> 420000 | O11: =IF($B11="","",G11*N11) -> 4200000 | P11: =IF($B11="","",IFERROR(INDEX(고객사!$K$5:$K$104,MATCH($B11,고객사!$A$5:$A$104,0)),0)) -> 330000 | Q11: =IF($B11="","",G11*P11) -> 3300000 | R11: =IF($B11="","",O11-Q11-L11) -> 900000 | S11: =IF(OR($B11="",N(O11)=0),"",R11/O11) -> 0.21428571 | U11: =IF(OR($B11="",$A11=""),0,IF(COUNTIFS($A$5:$A11,$A11,$B$5:$B11,$B11)=1,1,0)) -> 0
A12: 46267 | B12: C002 | C12: =IF($B12="","",IFERROR(INDEX(고객사!$B$5:$B$104,MATCH($B12,고객사!$A$5:$A$104,0)),"코드 확인")) -> 예시) 대성섬유 VN | D12: 봉제 | E12: 주간 | F12: 30 | G12: 30 | H12: =IF(OR($B12="",F12=0),"",G12/F12) -> 1 | I12: =IF($B12="","",MAX(F12-G12,0)) -> 0 | J12: =IF($B12="","",IFERROR(INDEX(고객사!$G$5:$G$104,MATCH($B12,고객사!$A$5:$A$104,0)),"")) -> N | K12: 1 | L12: =IF($B12="","",K12*IFERROR(INDEX(고객사!$L$5:$L$104,MATCH($B12,고객사!$A$5:$A$104,0)),0)) -> 1200000 | M12: =IF($B12="","",IF(AND(J12="N",G12>0,K12=0,IFERROR(INDEX(고객사!$H$5:$H$104,MATCH($B12,고객사!$A$5:$A$104,0)),"")="자사 차량 운행"),"차량 미배정","")) | N12: =IF($B12="","",IFERROR(INDEX(고객사!$J$5:$J$104,MATCH($B12,고객사!$A$5:$A$104,0)),0)) -> 380000 | O12: =IF($B12="","",G12*N12) -> 11400000 | P12: =IF($B12="","",IFERROR(INDEX(고객사!$K$5:$K$104,MATCH($B12,고객사!$A$5:$A$104,0)),0)) -> 300000 | Q12: =IF($B12="","",G12*P12) -> 9000000 | R12: =IF($B12="","",O12-Q12-L12) -> 1200000 | S12: =IF(OR($B12="",N(O12)=0),"",R12/O12) -> 0.10526316 | U12: =IF(OR($B12="",$A12=""),0,IF(COUNTIFS($A$5:$A12,$A12,$B$5:$B12,$B12)=1,1,0)) -> 1
A13: 46267 | B13: C003 | C13: =IF($B13="","",IFERROR(INDEX(고객사!$B$5:$B$104,MATCH($B13,고객사!$A$5:$A$104,0)),"코드 확인")) -> 예시) 그린물류 하노이 | D13: 물류·상하차 | E13: 주간 | F13: 18 | G13: 17 | H13: =IF(OR($B13="",F13=0),"",G13/F13) -> 0.94444444 | I13: =IF($B13="","",MAX(F13-G13,0)) -> 1 | J13: =IF($B13="","",IFERROR(INDEX(고객사!$G$5:$G$104,MATCH($B13,고객사!$A$5:$A$104,0)),"")) -> N | K13: 0 | L13: =IF($B13="","",K13*IFERROR(INDEX(고객사!$L$5:$L$104,MATCH($B13,고객사!$A$5:$A$104,0)),0)) -> 0 | M13: =IF($B13="","",IF(AND(J13="N",G13>0,K13=0,IFERROR(INDEX(고객사!$H$5:$H$104,MATCH($B13,고객사!$A$5:$A$104,0)),"")="자사 차량 운행"),"차량 미배정","")) | N13: =IF($B13="","",IFERROR(INDEX(고객사!$J$5:$J$104,MATCH($B13,고객사!$A$5:$A$104,0)),0)) -> 400000 | O13: =IF($B13="","",G13*N13) -> 6800000 | P13: =IF($B13="","",IFERROR(INDEX(고객사!$K$5:$K$104,MATCH($B13,고객사!$A$5:$A$104,0)),0)) -> 315000 | Q13: =IF($B13="","",G13*P13) -> 5355000 | R13: =IF($B13="","",O13-Q13-L13) -> 1445000 | S13: =IF(OR($B13="",N(O13)=0),"",R13/O13) -> 0.2125 | U13: =IF(OR($B13="",$A13=""),0,IF(COUNTIFS($A$5:$A13,$A13,$B$5:$B13,$B13)=1,1,0)) -> 1
A14: 46267 | B14: C004 | C14: =IF($B14="","",IFERROR(INDEX(고객사!$B$5:$B$104,MATCH($B14,고객사!$A$5:$A$104,0)),"코드 확인")) -> 예시) 미래식품 빈즈엉 | D14: 포장 | E14: 2교대 | F14: 22 | G14: 22 | H14: =IF(OR($B14="",F14=0),"",G14/F14) -> 1 | I14: =IF($B14="","",MAX(F14-G14,0)) -> 0 | J14: =IF($B14="","",IFERROR(INDEX(고객사!$G$5:$G$104,MATCH($B14,고객사!$A$5:$A$104,0)),"")) -> Y | K14: 0 | L14: =IF($B14="","",K14*IFERROR(INDEX(고객사!$L$5:$L$104,MATCH($B14,고객사!$A$5:$A$104,0)),0)) -> 0 | M14: =IF($B14="","",IF(AND(J14="N",G14>0,K14=0,IFERROR(INDEX(고객사!$H$5:$H$104,MATCH($B14,고객사!$A$5:$A$104,0)),"")="자사 차량 운행"),"차량 미배정","")) | N14: =IF($B14="","",IFERROR(INDEX(고객사!$J$5:$J$104,MATCH($B14,고객사!$A$5:$A$104,0)),0)) -> 390000 | O14: =IF($B14="","",G14*N14) -> 8580000 | P14: =IF($B14="","",IFERROR(INDEX(고객사!$K$5:$K$104,MATCH($B14,고객사!$A$5:$A$104,0)),0)) -> 305000 | Q14: =IF($B14="","",G14*P14) -> 6710000 | R14: =IF($B14="","",O14-Q14-L14) -> 1870000 | S14: =IF(OR($B14="",N(O14)=0),"",R14/O14) -> 0.21794872 | U14: =IF(OR($B14="",$A14=""),0,IF(COUNTIFS($A$5:$A14,$A14,$B$5:$B14,$B14)=1,1,0)) -> 1
A15: 46268 | B15: C001 | C15: =IF($B15="","",IFERROR(INDEX(고객사!$B$5:$B$104,MATCH($B15,고객사!$A$5:$A$104,0)),"코드 확인")) -> 예시) 한빛전자 비나 | D15: 생산 라인 | E15: 주간 | F15: 40 | G15: 40 | H15: =IF(OR($B15="",F15=0),"",G15/F15) -> 1 | I15: =IF($B15="","",MAX(F15-G15,0)) -> 0 | J15: =IF($B15="","",IFERROR(INDEX(고객사!$G$5:$G$104,MATCH($B15,고객사!$A$5:$A$104,0)),"")) -> Y | K15: 0 | L15: =IF($B15="","",K15*IFERROR(INDEX(고객사!$L$5:$L$104,MATCH($B15,고객사!$A$5:$A$104,0)),0)) -> 0 | M15: =IF($B15="","",IF(AND(J15="N",G15>0,K15=0,IFERROR(INDEX(고객사!$H$5:$H$104,MATCH($B15,고객사!$A$5:$A$104,0)),"")="자사 차량 운행"),"차량 미배정","")) | N15: =IF($B15="","",IFERROR(INDEX(고객사!$J$5:$J$104,MATCH($B15,고객사!$A$5:$A$104,0)),0)) -> 420000 | O15: =IF($B15="","",G15*N15) -> 16800000 | P15: =IF($B15="","",IFERROR(INDEX(고객사!$K$5:$K$104,MATCH($B15,고객사!$A$5:$A$104,0)),0)) -> 330000 | Q15: =IF($B15="","",G15*P15) -> 13200000 | R15: =IF($B15="","",O15-Q15-L15) -> 3600000 | S15: =IF(OR($B15="",N(O15)=0),"",R15/O15) -> 0.21428571 | U15: =IF(OR($B15="",$A15=""),0,IF(COUNTIFS($A$5:$A15,$A15,$B$5:$B15,$B15)=1,1,0)) -> 1
A16: 46268 | B16: C001 | C16: =IF($B16="","",IFERROR(INDEX(고객사!$B$5:$B$104,MATCH($B16,고객사!$A$5:$A$104,0)),"코드 확인")) -> 예시) 한빛전자 비나 | D16: 검사(QC) | E16: 야간 | F16: 12 | G16: 9 | H16: =IF(OR($B16="",F16=0),"",G16/F16) -> 0.75 | I16: =IF($B16="","",MAX(F16-G16,0)) -> 3 | J16: =IF($B16="","",IFERROR(INDEX(고객사!$G$5:$G$104,MATCH($B16,고객사!$A$5:$A$104,0)),"")) -> Y | K16: 0 | L16: =IF($B16="","",K16*IFERROR(INDEX(고객사!$L$5:$L$104,MATCH($B16,고객사!$A$5:$A$104,0)),0)) -> 0 | M16: =IF($B16="","",IF(AND(J16="N",G16>0,K16=0,IFERROR(INDEX(고객사!$H$5:$H$104,MATCH($B16,고객사!$A$5:$A$104,0)),"")="자사 차량 운행"),"차량 미배정","")) | N16: =IF($B16="","",IFERROR(INDEX(고객사!$J$5:$J$104,MATCH($B16,고객사!$A$5:$A$104,0)),0)) -> 420000 | O16: =IF($B16="","",G16*N16) -> 3780000 | P16: =IF($B16="","",IFERROR(INDEX(고객사!$K$5:$K$104,MATCH($B16,고객사!$A$5:$A$104,0)),0)) -> 330000 | Q16: =IF($B16="","",G16*P16) -> 2970000 | R16: =IF($B16="","",O16-Q16-L16) -> 810000 | S16: =IF(OR($B16="",N(O16)=0),"",R16/O16) -> 0.21428571 | U16: =IF(OR($B16="",$A16=""),0,IF(COUNTIFS($A$5:$A16,$A16,$B$5:$B16,$B16)=1,1,0)) -> 0
A17: 46268 | B17: C002 | C17: =IF($B17="","",IFERROR(INDEX(고객사!$B$5:$B$104,MATCH($B17,고객사!$A$5:$A$104,0)),"코드 확인")) -> 예시) 대성섬유 VN | D17: 봉제 | E17: 주간 | F17: 30 | G17: 27 | H17: =IF(OR($B17="",F17=0),"",G17/F17) -> 0.9 | I17: =IF($B17="","",MAX(F17-G17,0)) -> 3 | J17: =IF($B17="","",IFERROR(INDEX(고객사!$G$5:$G$104,MATCH($B17,고객사!$A$5:$A$104,0)),"")) -> N | K17: 1 | L17: =IF($B17="","",K17*IFERROR(INDEX(고객사!$L$5:$L$104,MATCH($B17,고객사!$A$5:$A$104,0)),0)) -> 1200000 | M17: =IF($B17="","",IF(AND(J17="N",G17>0,K17=0,IFERROR(INDEX(고객사!$H$5:$H$104,MATCH($B17,고객사!$A$5:$A$104,0)),"")="자사 차량 운행"),"차량 미배정","")) | N17: =IF($B17="","",IFERROR(INDEX(고객사!$J$5:$J$104,MATCH($B17,고객사!$A$5:$A$104,0)),0)) -> 380000 | O17: =IF($B17="","",G17*N17) -> 10260000 | P17: =IF($B17="","",IFERROR(INDEX(고객사!$K$5:$K$104,MATCH($B17,고객사!$A$5:$A$104,0)),0)) -> 300000 | Q17: =IF($B17="","",G17*P17) -> 8100000 | R17: =IF($B17="","",O17-Q17-L17) -> 960000 | S17: =IF(OR($B17="",N(O17)=0),"",R17/O17) -> 0.093567251 | U17: =IF(OR($B17="",$A17=""),0,IF(COUNTIFS($A$5:$A17,$A17,$B$5:$B17,$B17)=1,1,0)) -> 1
... A114: 46290 | B114: C004 | C114: =IF($B114="","",IFERROR(INDEX(고객사!$B$5:$B$104,MATCH($B114,고객사!$A$5:$A$104,0)),"코드 확인")) -> 예시) 미래식품 빈즈엉 | D114: 포장 | E114: 2교대 | F114: 22 | G114: 22 | H114: =IF(OR($B114="",F114=0),"",G114/F114) -> 1 | I114: =IF($B114="","",MAX(F114-G114,0)) -> 0 | J114: =IF($B114="","",IFERROR(INDEX(고객사!$G$5:$G$104,MATCH($B114,고객사!$A$5:$A$104,0)),"")) -> Y | K114: 0 | L114: =IF($B114="","",K114*IFERROR(INDEX(고객사!$L$5:$L$104,MATCH($B114,고객사!$A$5:$A$104,0)),0)) -> 0 | M114: =IF($B114="","",IF(AND(J114="N",G114>0,K114=0,IFERROR(INDEX(고객사!$H$5:$H$104,MATCH($B114,고객사!$A$5:$A$104,0)),"")="자사 차량 운행"),"차량 미배정","")) | N114: =IF($B114="","",IFERROR(INDEX(고객사!$J$5:$J$104,MATCH($B114,고객사!$A$5:$A$104,0)),0)) -> 390000 | O114: =IF($B114="","",G114*N114) -> 8580000 | P114: =IF($B114="","",IFERROR(INDEX(고객사!$K$5:$K$104,MATCH($B114,고객사!$A$5:$A$104,0)),0)) -> 305000 | Q114: =IF($B114="","",G114*P114) -> 6710000 | R114: =IF($B114="","",O114-Q114-L114) -> 1870000 | S114: =IF(OR($B114="",N(O114)=0),"",R114/O114) -> 0.21794872 | U114: =IF(OR($B114="",$A114=""),0,IF(COUNTIFS($A$5:$A114,$A114,$B$5:$B114,$B114)=1,1,0)) -> 1
C115: =IF($B115="","",IFERROR(INDEX(고객사!$B$5:$B$104,MATCH($B115,고객사!$A$5:$A$104,0)),"코드 확인")) | H115: =IF(OR($B115="",F115=0),"",G115/F115) | I115: =IF($B115="","",MAX(F115-G115,0)) | J115: =IF($B115="","",IFERROR(INDEX(고객사!$G$5:$G$104,MATCH($B115,고객사!$A$5:$A$104,0)),"")) | L115: =IF($B115="","",K115*IFERROR(INDEX(고객사!$L$5:$L$104,MATCH($B115,고객사!$A$5:$A$104,0)),0)) | M115: =IF($B115="","",IF(AND(J115="N",G115>0,K115=0,IFERROR(INDEX(고객사!$H$5:$H$104,MATCH($B115,고객사!$A$5:$A$104,0)),"")="자사 차량 운행"),"차량 미배정","")) | N115: =IF($B115="","",IFERROR(INDEX(고객사!$J$5:$J$104,MATCH($B115,고객사!$A$5:$A$104,0)),0)) | O115: =IF($B115="","",G115*N115) | P115: =IF($B115="","",IFERROR(INDEX(고객사!$K$5:$K$104,MATCH($B115,고객사!$A$5:$A$104,0)),0)) | Q115: =IF($B115="","",G115*P115) | R115: =IF($B115="","",O115-Q115-L115) | S115: =IF(OR($B115="",N(O115)=0),"",R115/O115) | U115: =IF(OR($B115="",$A115=""),0,IF(COUNTIFS($A$5:$A115,$A115,$B$5:$B115,$B115)=1,1,0)) -> 0
C116: =IF($B116="","",IFERROR(INDEX(고객사!$B$5:$B$104,MATCH($B116,고객사!$A$5:$A$104,0)),"코드 확인")) | H116: =IF(OR($B116="",F116=0),"",G116/F116) | I116: =IF($B116="","",MAX(F116-G116,0)) | J116: =IF($B116="","",IFERROR(INDEX(고객사!$G$5:$G$104,MATCH($B116,고객사!$A$5:$A$104,0)),"")) | L116: =IF($B116="","",K116*IFERROR(INDEX(고객사!$L$5:$L$104,MATCH($B116,고객사!$A$5:$A$104,0)),0)) | M116: =IF($B116="","",IF(AND(J116="N",G116>0,K116=0,IFERROR(INDEX(고객사!$H$5:$H$104,MATCH($B116,고객사!$A$5:$A$104,0)),"")="자사 차량 운행"),"차량 미배정","")) | N116: =IF($B116="","",IFERROR(INDEX(고객사!$J$5:$J$104,MATCH($B116,고객사!$A$5:$A$104,0)),0)) | O116: =IF($B116="","",G116*N116) | P116: =IF($B116="","",IFERROR(INDEX(고객사!$K$5:$K$104,MATCH($B116,고객사!$A$5:$A$104,0)),0)) | Q116: =IF($B116="","",G116*P116) | R116: =IF($B116="","",O116-Q116-L116) | S116: =IF(OR($B116="",N(O116)=0),"",R116/O116) | U116: =IF(OR($B116="",$A116=""),0,IF(COUNTIFS($A$5:$A116,$A116,$B$5:$B116,$B116)=1,1,0)) -> 0
C117: =IF($B117="","",IFERROR(INDEX(고객사!$B$5:$B$104,MATCH($B117,고객사!$A$5:$A$104,0)),"코드 확인")) | H117: =IF(OR($B117="",F117=0),"",G117/F117) | I117: =IF($B117="","",MAX(F117-G117,0)) | J117: =IF($B117="","",IFERROR(INDEX(고객사!$G$5:$G$104,MATCH($B117,고객사!$A$5:$A$104,0)),"")) | L117: =IF($B117="","",K117*IFERROR(INDEX(고객사!$L$5:$L$104,MATCH($B117,고객사!$A$5:$A$104,0)),0)) | M117: =IF($B117="","",IF(AND(J117="N",G117>0,K117=0,IFERROR(INDEX(고객사!$H$5:$H$104,MATCH($B117,고객사!$A$5:$A$104,0)),"")="자사 차량 운행"),"차량 미배정","")) | N117: =IF($B117="","",IFERROR(INDEX(고객사!$J$5:$J$104,MATCH($B117,고객사!$A$5:$A$104,0)),0)) | O117: =IF($B117="","",G117*N117) | P117: =IF($B117="","",IFERROR(INDEX(고객사!$K$5:$K$104,MATCH($B117,고객사!$A$5:$A$104,0)),0)) | Q117: =IF($B117="","",G117*P117) | R117: =IF($B117="","",O117-Q117-L117) | S117: =IF(OR($B117="",N(O117)=0),"",R117/O117) | U117: =IF(OR($B117="",$A117=""),0,IF(COUNTIFS($A$5:$A117,$A117,$B$5:$B117,$B117)=1,1,0)) -> 0
C118: =IF($B118="","",IFERROR(INDEX(고객사!$B$5:$B$104,MATCH($B118,고객사!$A$5:$A$104,0)),"코드 확인")) | H118: =IF(OR($B118="",F118=0),"",G118/F118) | I118: =IF($B118="","",MAX(F118-G118,0)) | J118: =IF($B118="","",IFERROR(INDEX(고객사!$G$5:$G$104,MATCH($B118,고객사!$A$5:$A$104,0)),"")) | L118: =IF($B118="","",K118*IFERROR(INDEX(고객사!$L$5:$L$104,MATCH($B118,고객사!$A$5:$A$104,0)),0)) | M118: =IF($B118="","",IF(AND(J118="N",G118>0,K118=0,IFERROR(INDEX(고객사!$H$5:$H$104,MATCH($B118,고객사!$A$5:$A$104,0)),"")="자사 차량 운행"),"차량 미배정","")) | N118: =IF($B118="","",IFERROR(INDEX(고객사!$J$5:$J$104,MATCH($B118,고객사!$A$5:$A$104,0)),0)) | O118: =IF($B118="","",G118*N118) | P118: =IF($B118="","",IFERROR(INDEX(고객사!$K$5:$K$104,MATCH($B118,고객사!$A$5:$A$104,0)),0)) | Q118: =IF($B118="","",G118*P118) | R118: =IF($B118="","",O118-Q118-L118) | S118: =IF(OR($B118="",N(O118)=0),"",R118/O118) | U118: =IF(OR($B118="",$A118=""),0,IF(COUNTIFS($A$5:$A118,$A118,$B$5:$B118,$B118)=1,1,0)) -> 0
C119: =IF($B119="","",IFERROR(INDEX(고객사!$B$5:$B$104,MATCH($B119,고객사!$A$5:$A$104,0)),"코드 확인")) | H119: =IF(OR($B119="",F119=0),"",G119/F119) | I119: =IF($B119="","",MAX(F119-G119,0)) | J119: =IF($B119="","",IFERROR(INDEX(고객사!$G$5:$G$104,MATCH($B119,고객사!$A$5:$A$104,0)),"")) | L119: =IF($B119="","",K119*IFERROR(INDEX(고객사!$L$5:$L$104,MATCH($B119,고객사!$A$5:$A$104,0)),0)) | M119: =IF($B119="","",IF(AND(J119="N",G119>0,K119=0,IFERROR(INDEX(고객사!$H$5:$H$104,MATCH($B119,고객사!$A$5:$A$104,0)),"")="자사 차량 운행"),"차량 미배정","")) | N119: =IF($B119="","",IFERROR(INDEX(고객사!$J$5:$J$104,MATCH($B119,고객사!$A$5:$A$104,0)),0)) | O119: =IF($B119="","",G119*N119) | P119: =IF($B119="","",IFERROR(INDEX(고객사!$K$5:$K$104,MATCH($B119,고객사!$A$5:$A$104,0)),0)) | Q119: =IF($B119="","",G119*P119) | R119: =IF($B119="","",O119-Q119-L119) | S119: =IF(OR($B119="",N(O119)=0),"",R119/O119) | U119: =IF(OR($B119="",$A119=""),0,IF(COUNTIFS($A$5:$A119,$A119,$B$5:$B119,$B119)=1,1,0)) -> 0
C120: =IF($B120="","",IFERROR(INDEX(고객사!$B$5:$B$104,MATCH($B120,고객사!$A$5:$A$104,0)),"코드 확인")) | H120: =IF(OR($B120="",F120=0),"",G120/F120) | I120: =IF($B120="","",MAX(F120-G120,0)) | J120: =IF($B120="","",IFERROR(INDEX(고객사!$G$5:$G$104,MATCH($B120,고객사!$A$5:$A$104,0)),"")) | L120: =IF($B120="","",K120*IFERROR(INDEX(고객사!$L$5:$L$104,MATCH($B120,고객사!$A$5:$A$104,0)),0)) | M120: =IF($B120="","",IF(AND(J120="N",G120>0,K120=0,IFERROR(INDEX(고객사!$H$5:$H$104,MATCH($B120,고객사!$A$5:$A$104,0)),"")="자사 차량 운행"),"차량 미배정","")) | N120: =IF($B120="","",IFERROR(INDEX(고객사!$J$5:$J$104,MATCH($B120,고객사!$A$5:$A$104,0)),0)) | O120: =IF($B120="","",G120*N120) | P120: =IF($B120="","",IFERROR(INDEX(고객사!$K$5:$K$104,MATCH($B120,고객사!$A$5:$A$104,0)),0)) | Q120: =IF($B120="","",G120*P120) | R120: =IF($B120="","",O120-Q120-L120) | S120: =IF(OR($B120="",N(O120)=0),"",R120/O120) | U120: =IF(OR($B120="",$A120=""),0,IF(COUNTIFS($A$5:$A120,$A120,$B$5:$B120,$B120)=1,1,0)) -> 0
C121: =IF($B121="","",IFERROR(INDEX(고객사!$B$5:$B$104,MATCH($B121,고객사!$A$5:$A$104,0)),"코드 확인")) | H121: =IF(OR($B121="",F121=0),"",G121/F121) | I121: =IF($B121="","",MAX(F121-G121,0)) | J121: =IF($B121="","",IFERROR(INDEX(고객사!$G$5:$G$104,MATCH($B121,고객사!$A$5:$A$104,0)),"")) | L121: =IF($B121="","",K121*IFERROR(INDEX(고객사!$L$5:$L$104,MATCH($B121,고객사!$A$5:$A$104,0)),0)) | M121: =IF($B121="","",IF(AND(J121="N",G121>0,K121=0,IFERROR(INDEX(고객사!$H$5:$H$104,MATCH($B121,고객사!$A$5:$A$104,0)),"")="자사 차량 운행"),"차량 미배정","")) | N121: =IF($B121="","",IFERROR(INDEX(고객사!$J$5:$J$104,MATCH($B121,고객사!$A$5:$A$104,0)),0)) | O121: =IF($B121="","",G121*N121) | P121: =IF($B121="","",IFERROR(INDEX(고객사!$K$5:$K$104,MATCH($B121,고객사!$A$5:$A$104,0)),0)) | Q121: =IF($B121="","",G121*P121) | R121: =IF($B121="","",O121-Q121-L121) | S121: =IF(OR($B121="",N(O121)=0),"",R121/O121) | U121: =IF(OR($B121="",$A121=""),0,IF(COUNTIFS($A$5:$A121,$A121,$B$5:$B121,$B121)=1,1,0)) -> 0
C122: =IF($B122="","",IFERROR(INDEX(고객사!$B$5:$B$104,MATCH($B122,고객사!$A$5:$A$104,0)),"코드 확인")) | H122: =IF(OR($B122="",F122=0),"",G122/F122) | I122: =IF($B122="","",MAX(F122-G122,0)) | J122: =IF($B122="","",IFERROR(INDEX(고객사!$G$5:$G$104,MATCH($B122,고객사!$A$5:$A$104,0)),"")) | L122: =IF($B122="","",K122*IFERROR(INDEX(고객사!$L$5:$L$104,MATCH($B122,고객사!$A$5:$A$104,0)),0)) | M122: =IF($B122="","",IF(AND(J122="N",G122>0,K122=0,IFERROR(INDEX(고객사!$H$5:$H$104,MATCH($B122,고객사!$A$5:$A$104,0)),"")="자사 차량 운행"),"차량 미배정","")) | N122: =IF($B122="","",IFERROR(INDEX(고객사!$J$5:$J$104,MATCH($B122,고객사!$A$5:$A$104,0)),0)) | O122: =IF($B122="","",G122*N122) | P122: =IF($B122="","",IFERROR(INDEX(고객사!$K$5:$K$104,MATCH($B122,고객사!$A$5:$A$104,0)),0)) | Q122: =IF($B122="","",G122*P122) | R122: =IF($B122="","",O122-Q122-L122) | S122: =IF(OR($B122="",N(O122)=0),"",R122/O122) | U122: =IF(OR($B122="",$A122=""),0,IF(COUNTIFS($A$5:$A122,$A122,$B$5:$B122,$B122)=1,1,0)) -> 0
C123: =IF($B123="","",IFERROR(INDEX(고객사!$B$5:$B$104,MATCH($B123,고객사!$A$5:$A$104,0)),"코드 확인")) | H123: =IF(OR($B123="",F123=0),"",G123/F123) | I123: =IF($B123="","",MAX(F123-G123,0)) | J123: =IF($B123="","",IFERROR(INDEX(고객사!$G$5:$G$104,MATCH($B123,고객사!$A$5:$A$104,0)),"")) | L123: =IF($B123="","",K123*IFERROR(INDEX(고객사!$L$5:$L$104,MATCH($B123,고객사!$A$5:$A$104,0)),0)) | M123: =IF($B123="","",IF(AND(J123="N",G123>0,K123=0,IFERROR(INDEX(고객사!$H$5:$H$104,MATCH($B123,고객사!$A$5:$A$104,0)),"")="자사 차량 운행"),"차량 미배정","")) | N123: =IF($B123="","",IFERROR(INDEX(고객사!$J$5:$J$104,MATCH($B123,고객사!$A$5:$A$104,0)),0)) | O123: =IF($B123="","",G123*N123) | P123: =IF($B123="","",IFERROR(INDEX(고객사!$K$5:$K$104,MATCH($B123,고객사!$A$5:$A$104,0)),0)) | Q123: =IF($B123="","",G123*P123) | R123: =IF($B123="","",O123-Q123-L123) | S123: =IF(OR($B123="",N(O123)=0),"",R123/O123) | U123: =IF(OR($B123="",$A123=""),0,IF(COUNTIFS($A$5:$A123,$A123,$B$5:$B123,$B123)=1,1,0)) -> 0
C124: =IF($B124="","",IFERROR(INDEX(고객사!$B$5:$B$104,MATCH($B124,고객사!$A$5:$A$104,0)),"코드 확인")) | H124: =IF(OR($B124="",F124=0),"",G124/F124) | I124: =IF($B124="","",MAX(F124-G124,0)) | J124: =IF($B124="","",IFERROR(INDEX(고객사!$G$5:$G$104,MATCH($B124,고객사!$A$5:$A$104,0)),"")) | L124: =IF($B124="","",K124*IFERROR(INDEX(고객사!$L$5:$L$104,MATCH($B124,고객사!$A$5:$A$104,0)),0)) | M124: =IF($B124="","",IF(AND(J124="N",G124>0,K124=0,IFERROR(INDEX(고객사!$H$5:$H$104,MATCH($B124,고객사!$A$5:$A$104,0)),"")="자사 차량 운행"),"차량 미배정","")) | N124: =IF($B124="","",IFERROR(INDEX(고객사!$J$5:$J$104,MATCH($B124,고객사!$A$5:$A$104,0)),0)) | O124: =IF($B124="","",G124*N124) | P124: =IF($B124="","",IFERROR(INDEX(고객사!$K$5:$K$104,MATCH($B124,고객사!$A$5:$A$104,0)),0)) | Q124: =IF($B124="","",G124*P124) | R124: =IF($B124="","",O124-Q124-L124) | S124: =IF(OR($B124="",N(O124)=0),"",R124/O124) | U124: =IF(OR($B124="",$A124=""),0,IF(COUNTIFS($A$5:$A124,$A124,$B$5:$B124,$B124)=1,1,0)) -> 0
C125: =IF($B125="","",IFERROR(INDEX(고객사!$B$5:$B$104,MATCH($B125,고객사!$A$5:$A$104,0)),"코드 확인")) | H125: =IF(OR($B125="",F125=0),"",G125/F125) | I125: =IF($B125="","",MAX(F125-G125,0)) | J125: =IF($B125="","",IFERROR(INDEX(고객사!$G$5:$G$104,MATCH($B125,고객사!$A$5:$A$104,0)),"")) | L125: =IF($B125="","",K125*IFERROR(INDEX(고객사!$L$5:$L$104,MATCH($B125,고객사!$A$5:$A$104,0)),0)) | M125: =IF($B125="","",IF(AND(J125="N",G125>0,K125=0,IFERROR(INDEX(고객사!$H$5:$H$104,MATCH($B125,고객사!$A$5:$A$104,0)),"")="자사 차량 운행"),"차량 미배정","")) | N125: =IF($B125="","",IFERROR(INDEX(고객사!$J$5:$J$104,MATCH($B125,고객사!$A$5:$A$104,0)),0)) | O125: =IF($B125="","",G125*N125) | P125: =IF($B125="","",IFERROR(INDEX(고객사!$K$5:$K$104,MATCH($B125,고객사!$A$5:$A$104,0)),0)) | Q125: =IF($B125="","",G125*P125) | R125: =IF($B125="","",O125-Q125-L125) | S125: =IF(OR($B125="",N(O125)=0),"",R125/O125) | U125: =IF(OR($B125="",$A125=""),0,IF(COUNTIFS($A$5:$A125,$A125,$B$5:$B125,$B125)=1,1,0)) -> 0
C126: =IF($B126="","",IFERROR(INDEX(고객사!$B$5:$B$104,MATCH($B126,고객사!$A$5:$A$104,0)),"코드 확인")) | H126: =IF(OR($B126="",F126=0),"",G126/F126) | I126: =IF($B126="","",MAX(F126-G126,0)) | J126: =IF($B126="","",IFERROR(INDEX(고객사!$G$5:$G$104,MATCH($B126,고객사!$A$5:$A$104,0)),"")) | L126: =IF($B126="","",K126*IFERROR(INDEX(고객사!$L$5:$L$104,MATCH($B126,고객사!$A$5:$A$104,0)),0)) | M126: =IF($B126="","",IF(AND(J126="N",G126>0,K126=0,IFERROR(INDEX(고객사!$H$5:$H$104,MATCH($B126,고객사!$A$5:$A$104,0)),"")="자사 차량 운행"),"차량 미배정","")) | N126: =IF($B126="","",IFERROR(INDEX(고객사!$J$5:$J$104,MATCH($B126,고객사!$A$5:$A$104,0)),0)) | O126: =IF($B126="","",G126*N126) | P126: =IF($B126="","",IFERROR(INDEX(고객사!$K$5:$K$104,MATCH($B126,고객사!$A$5:$A$104,0)),0)) | Q126: =IF($B126="","",G126*P126) | R126: =IF($B126="","",O126-Q126-L126) | S126: =IF(OR($B126="",N(O126)=0),"",R126/O126) | U126: =IF(OR($B126="",$A126=""),0,IF(COUNTIFS($A$5:$A126,$A126,$B$5:$B126,$B126)=1,1,0)) -> 0
... C2004: =IF($B2004="","",IFERROR(INDEX(고객사!$B$5:$B$104,MATCH($B2004,고객사!$A$5:$A$104,0)),"코드 확인")) | H2004: =IF(OR($B2004="",F2004=0),"",G2004/F2004) | I2004: =IF($B2004="","",MAX(F2004-G2004,0)) | J2004: =IF($B2004="","",IFERROR(INDEX(고객사!$G$5:$G$104,MATCH($B2004,고객사!$A$5:$A$104,0)),"")) | L2004: =IF($B2004="","",K2004*IFERROR(INDEX(고객사!$L$5:$L$104,MATCH($B2004,고객사!$A$5:$A$104,0)),0)) | M2004: =IF($B2004="","",IF(AND(J2004="N",G2004>0,K2004=0,IFERROR(INDEX(고객사!$H$5:$H$104,MATCH($B2004,고객사!$A$5:$A$104,0)),"")="자사 차량 운행"),"차량 미배정","")) | N2004: =IF($B2004="","",IFERROR(INDEX(고객사!$J$5:$J$104,MATCH($B2004,고객사!$A$5:$A$104,0)),0)) | O2004: =IF($B2004="","",G2004*N2004) | P2004: =IF($B2004="","",IFERROR(INDEX(고객사!$K$5:$K$104,MATCH($B2004,고객사!$A$5:$A$104,0)),0)) | Q2004: =IF($B2004="","",G2004*P2004) | R2004: =IF($B2004="","",O2004-Q2004-L2004) | S2004: =IF(OR($B2004="",N(O2004)=0),"",R2004/O2004) | U2004: =IF(OR($B2004="",$A2004=""),0,IF(COUNTIFS($A$5:$A2004,$A2004,$B$5:$B2004,$B2004)=1,1,0)) -> 0

Sheet 월간요약
A1: 월간 계획 / 실적 요약 — Báo cáo tháng
A2: C3 기준월만 바꾸면 전체가 다시 계산됩니다. 인원은 '연인원(인·일)' 기준입니다.
A3: 기준월 / Tháng | C3: 46266 | E3: 월 시작 | F3: =DATE(YEAR($C$3),MONTH($C$3),1) -> 46266 | G3: 다음 달 시작 | H3: =EDATE($F$3,1) -> 46296
A5: 고객사코드 Mã KH | B5: 고객사명 Tên KH | C5: 차량지원 Hỗ trợ xe | D5: 운영일수 Số ngày | E5: 계획 연인원 Kế hoạch | F5: 실적 연인원 Thực tế | G5: 달성률 Tỷ lệ đạt | H5: 결원 합계 Thiếu | I5: 매출(VND) Doanh thu | J5: 인건비(VND) Lương | K5: 차량비(VND) Chi phí xe | L5: 이익(VND) Lợi nhuận | M5: 이익률 Tỷ suất
A6: =IF(고객사!$A$5="","",고객사!$A$5) -> C001 | B6: =IF($A6="","",고객사!$B$5) -> 예시) 한빛전자 비나 | C6: =IF($A6="","",고객사!$G$5) -> Y | D6: =IF($A6="","",SUMIFS(일일계획실적!$U$5:$U$2004,일일계획실적!$B$5:$B$2004,$A6,일일계획실적!$A$5:$A$2004,">="&$F$3,일일계획실적!$A$5:$A$2004,"<"&$H$3)) -> 22 | E6: =IF($A6="","",SUMIFS(일일계획실적!$F$5:$F$2004,일일계획실적!$B$5:$B$2004,$A6,일일계획실적!$A$5:$A$2004,">="&$F$3,일일계획실적!$A$5:$A$2004,"<"&$H$3)) -> 1144 | F6: =IF($A6="","",SUMIFS(일일계획실적!$G$5:$G$2004,일일계획실적!$B$5:$B$2004,$A6,일일계획실적!$A$5:$A$2004,">="&$F$3,일일계획실적!$A$5:$A$2004,"<"&$H$3)) -> 1091 | G6: =IF(OR($A6="",N(E6)=0),"",F6/E6) -> 0.95367133 | H6: =IF($A6="","",SUMIFS(일일계획실적!$I$5:$I$2004,일일계획실적!$B$5:$B$2004,$A6,일일계획실적!$A$5:$A$2004,">="&$F$3,일일계획실적!$A$5:$A$2004,"<"&$H$3)) -> 53 | I6: =IF($A6="","",SUMIFS(일일계획실적!$O$5:$O$2004,일일계획실적!$B$5:$B$2004,$A6,일일계획실적!$A$5:$A$2004,">="&$F$3,일일계획실적!$A$5:$A$2004,"<"&$H$3)) -> 458220000 | J6: =IF($A6="","",SUMIFS(일일계획실적!$Q$5:$Q$2004,일일계획실적!$B$5:$B$2004,$A6,일일계획실적!$A$5:$A$2004,">="&$F$3,일일계획실적!$A$5:$A$2004,"<"&$H$3)) -> 360030000 | K6: =IF($A6="","",SUMIFS(일일계획실적!$L$5:$L$2004,일일계획실적!$B$5:$B$2004,$A6,일일계획실적!$A$5:$A$2004,">="&$F$3,일일계획실적!$A$5:$A$2004,"<"&$H$3)) -> 0 | L6: =IF($A6="","",I6-J6-K6) -> 98190000 | M6: =IF(OR($A6="",N(I6)=0),"",L6/I6) -> 0.21428571
A7: =IF(고객사!$A$6="","",고객사!$A$6) -> C002 | B7: =IF($A7="","",고객사!$B$6) -> 예시) 대성섬유 VN | C7: =IF($A7="","",고객사!$G$6) -> N | D7: =IF($A7="","",SUMIFS(일일계획실적!$U$5:$U$2004,일일계획실적!$B$5:$B$2004,$A7,일일계획실적!$A$5:$A$2004,">="&$F$3,일일계획실적!$A$5:$A$2004,"<"&$H$3)) -> 22 | E7: =IF($A7="","",SUMIFS(일일계획실적!$F$5:$F$2004,일일계획실적!$B$5:$B$2004,$A7,일일계획실적!$A$5:$A$2004,">="&$F$3,일일계획실적!$A$5:$A$2004,"<"&$H$3)) -> 660 | F7: =IF($A7="","",SUMIFS(일일계획실적!$G$5:$G$2004,일일계획실적!$B$5:$B$2004,$A7,일일계획실적!$A$5:$A$2004,">="&$F$3,일일계획실적!$A$5:$A$2004,"<"&$H$3)) -> 616 | G7: =IF(OR($A7="",N(E7)=0),"",F7/E7) -> 0.93333333 | H7: =IF($A7="","",SUMIFS(일일계획실적!$I$5:$I$2004,일일계획실적!$B$5:$B$2004,$A7,일일계획실적!$A$5:$A$2004,">="&$F$3,일일계획실적!$A$5:$A$2004,"<"&$H$3)) -> 44 | I7: =IF($A7="","",SUMIFS(일일계획실적!$O$5:$O$2004,일일계획실적!$B$5:$B$2004,$A7,일일계획실적!$A$5:$A$2004,">="&$F$3,일일계획실적!$A$5:$A$2004,"<"&$H$3)) -> 234080000 | J7: =IF($A7="","",SUMIFS(일일계획실적!$Q$5:$Q$2004,일일계획실적!$B$5:$B$2004,$A7,일일계획실적!$A$5:$A$2004,">="&$F$3,일일계획실적!$A$5:$A$2004,"<"&$H$3)) -> 184800000 | K7: =IF($A7="","",SUMIFS(일일계획실적!$L$5:$L$2004,일일계획실적!$B$5:$B$2004,$A7,일일계획실적!$A$5:$A$2004,">="&$F$3,일일계획실적!$A$5:$A$2004,"<"&$H$3)) -> 26400000 | L7: =IF($A7="","",I7-J7-K7) -> 22880000 | M7: =IF(OR($A7="",N(I7)=0),"",L7/I7) -> 0.097744361
A8: =IF(고객사!$A$7="","",고객사!$A$7) -> C003 | B8: =IF($A8="","",고객사!$B$7) -> 예시) 그린물류 하노이 | C8: =IF($A8="","",고객사!$G$7) -> N | D8: =IF($A8="","",SUMIFS(일일계획실적!$U$5:$U$2004,일일계획실적!$B$5:$B$2004,$A8,일일계획실적!$A$5:$A$2004,">="&$F$3,일일계획실적!$A$5:$A$2004,"<"&$H$3)) -> 22 | E8: =IF($A8="","",SUMIFS(일일계획실적!$F$5:$F$2004,일일계획실적!$B$5:$B$2004,$A8,일일계획실적!$A$5:$A$2004,">="&$F$3,일일계획실적!$A$5:$A$2004,"<"&$H$3)) -> 396 | F8: =IF($A8="","",SUMIFS(일일계획실적!$G$5:$G$2004,일일계획실적!$B$5:$B$2004,$A8,일일계획실적!$A$5:$A$2004,">="&$F$3,일일계획실적!$A$5:$A$2004,"<"&$H$3)) -> 358 | G8: =IF(OR($A8="",N(E8)=0),"",F8/E8) -> 0.9040404 | H8: =IF($A8="","",SUMIFS(일일계획실적!$I$5:$I$2004,일일계획실적!$B$5:$B$2004,$A8,일일계획실적!$A$5:$A$2004,">="&$F$3,일일계획실적!$A$5:$A$2004,"<"&$H$3)) -> 38 | I8: =IF($A8="","",SUMIFS(일일계획실적!$O$5:$O$2004,일일계획실적!$B$5:$B$2004,$A8,일일계획실적!$A$5:$A$2004,">="&$F$3,일일계획실적!$A$5:$A$2004,"<"&$H$3)) -> 143200000 | J8: =IF($A8="","",SUMIFS(일일계획실적!$Q$5:$Q$2004,일일계획실적!$B$5:$B$2004,$A8,일일계획실적!$A$5:$A$2004,">="&$F$3,일일계획실적!$A$5:$A$2004,"<"&$H$3)) -> 112770000 | K8: =IF($A8="","",SUMIFS(일일계획실적!$L$5:$L$2004,일일계획실적!$B$5:$B$2004,$A8,일일계획실적!$A$5:$A$2004,">="&$F$3,일일계획실적!$A$5:$A$2004,"<"&$H$3)) -> 0 | L8: =IF($A8="","",I8-J8-K8) -> 30430000 | M8: =IF(OR($A8="",N(I8)=0),"",L8/I8) -> 0.2125
A9: =IF(고객사!$A$8="","",고객사!$A$8) -> C004 | B9: =IF($A9="","",고객사!$B$8) -> 예시) 미래식품 빈즈엉 | C9: =IF($A9="","",고객사!$G$8) -> Y | D9: =IF($A9="","",SUMIFS(일일계획실적!$U$5:$U$2004,일일계획실적!$B$5:$B$2004,$A9,일일계획실적!$A$5:$A$2004,">="&$F$3,일일계획실적!$A$5:$A$2004,"<"&$H$3)) -> 22 | E9: =IF($A9="","",SUMIFS(일일계획실적!$F$5:$F$2004,일일계획실적!$B$5:$B$2004,$A9,일일계획실적!$A$5:$A$2004,">="&$F$3,일일계획실적!$A$5:$A$2004,"<"&$H$3)) -> 484 | F9: =IF($A9="","",SUMIFS(일일계획실적!$G$5:$G$2004,일일계획실적!$B$5:$B$2004,$A9,일일계획실적!$A$5:$A$2004,">="&$F$3,일일계획실적!$A$5:$A$2004,"<"&$H$3)) -> 453 | G9: =IF(OR($A9="",N(E9)=0),"",F9/E9) -> 0.93595041 | H9: =IF($A9="","",SUMIFS(일일계획실적!$I$5:$I$2004,일일계획실적!$B$5:$B$2004,$A9,일일계획실적!$A$5:$A$2004,">="&$F$3,일일계획실적!$A$5:$A$2004,"<"&$H$3)) -> 31 | I9: =IF($A9="","",SUMIFS(일일계획실적!$O$5:$O$2004,일일계획실적!$B$5:$B$2004,$A9,일일계획실적!$A$5:$A$2004,">="&$F$3,일일계획실적!$A$5:$A$2004,"<"&$H$3)) -> 176670000 | J9: =IF($A9="","",SUMIFS(일일계획실적!$Q$5:$Q$2004,일일계획실적!$B$5:$B$2004,$A9,일일계획실적!$A$5:$A$2004,">="&$F$3,일일계획실적!$A$5:$A$2004,"<"&$H$3)) -> 138165000 | K9: =IF($A9="","",SUMIFS(일일계획실적!$L$5:$L$2004,일일계획실적!$B$5:$B$2004,$A9,일일계획실적!$A$5:$A$2004,">="&$F$3,일일계획실적!$A$5:$A$2004,"<"&$H$3)) -> 0 | L9: =IF($A9="","",I9-J9-K9) -> 38505000 | M9: =IF(OR($A9="",N(I9)=0),"",L9/I9) -> 0.21794872
A10: =IF(고객사!$A$9="","",고객사!$A$9) | B10: =IF($A10="","",고객사!$B$9) | C10: =IF($A10="","",고객사!$G$9) | D10: =IF($A10="","",SUMIFS(일일계획실적!$U$5:$U$2004,일일계획실적!$B$5:$B$2004,$A10,일일계획실적!$A$5:$A$2004,">="&$F$3,일일계획실적!$A$5:$A$2004,"<"&$H$3)) | E10: =IF($A10="","",SUMIFS(일일계획실적!$F$5:$F$2004,일일계획실적!$B$5:$B$2004,$A10,일일계획실적!$A$5:$A$2004,">="&$F$3,일일계획실적!$A$5:$A$2004,"<"&$H$3)) | F10: =IF($A10="","",SUMIFS(일일계획실적!$G$5:$G$2004,일일계획실적!$B$5:$B$2004,$A10,일일계획실적!$A$5:$A$2004,">="&$F$3,일일계획실적!$A$5:$A$2004,"<"&$H$3)) | G10: =IF(OR($A10="",N(E10)=0),"",F10/E10) | H10: =IF($A10="","",SUMIFS(일일계획실적!$I$5:$I$2004,일일계획실적!$B$5:$B$2004,$A10,일일계획실적!$A$5:$A$2004,">="&$F$3,일일계획실적!$A$5:$A$2004,"<"&$H$3)) | I10: =IF($A10="","",SUMIFS(일일계획실적!$O$5:$O$2004,일일계획실적!$B$5:$B$2004,$A10,일일계획실적!$A$5:$A$2004,">="&$F$3,일일계획실적!$A$5:$A$2004,"<"&$H$3)) | J10: =IF($A10="","",SUMIFS(일일계획실적!$Q$5:$Q$2004,일일계획실적!$B$5:$B$2004,$A10,일일계획실적!$A$5:$A$2004,">="&$F$3,일일계획실적!$A$5:$A$2004,"<"&$H$3)) | K10: =IF($A10="","",SUMIFS(일일계획실적!$L$5:$L$2004,일일계획실적!$B$5:$B$2004,$A10,일일계획실적!$A$5:$A$2004,">="&$F$3,일일계획실적!$A$5:$A$2004,"<"&$H$3)) | L10: =IF($A10="","",I10-J10-K10) | M10: =IF(OR($A10="",N(I10)=0),"",L10/I10)
A11: =IF(고객사!$A$10="","",고객사!$A$10) | B11: =IF($A11="","",고객사!$B$10) | C11: =IF($A11="","",고객사!$G$10) | D11: =IF($A11="","",SUMIFS(일일계획실적!$U$5:$U$2004,일일계획실적!$B$5:$B$2004,$A11,일일계획실적!$A$5:$A$2004,">="&$F$3,일일계획실적!$A$5:$A$2004,"<"&$H$3)) | E11: =IF($A11="","",SUMIFS(일일계획실적!$F$5:$F$2004,일일계획실적!$B$5:$B$2004,$A11,일일계획실적!$A$5:$A$2004,">="&$F$3,일일계획실적!$A$5:$A$2004,"<"&$H$3)) | F11: =IF($A11="","",SUMIFS(일일계획실적!$G$5:$G$2004,일일계획실적!$B$5:$B$2004,$A11,일일계획실적!$A$5:$A$2004,">="&$F$3,일일계획실적!$A$5:$A$2004,"<"&$H$3)) | G11: =IF(OR($A11="",N(E11)=0),"",F11/E11) | H11: =IF($A11="","",SUMIFS(일일계획실적!$I$5:$I$2004,일일계획실적!$B$5:$B$2004,$A11,일일계획실적!$A$5:$A$2004,">="&$F$3,일일계획실적!$A$5:$A$2004,"<"&$H$3)) | I11: =IF($A11="","",SUMIFS(일일계획실적!$O$5:$O$2004,일일계획실적!$B$5:$B$2004,$A11,일일계획실적!$A$5:$A$2004,">="&$F$3,일일계획실적!$A$5:$A$2004,"<"&$H$3)) | J11: =IF($A11="","",SUMIFS(일일계획실적!$Q$5:$Q$2004,일일계획실적!$B$5:$B$2004,$A11,일일계획실적!$A$5:$A$2004,">="&$F$3,일일계획실적!$A$5:$A$2004,"<"&$H$3)) | K11: =IF($A11="","",SUMIFS(일일계획실적!$L$5:$L$2004,일일계획실적!$B$5:$B$2004,$A11,일일계획실적!$A$5:$A$2004,">="&$F$3,일일계획실적!$A$5:$A$2004,"<"&$H$3)) | L11: =IF($A11="","",I11-J11-K11) | M11: =IF(OR($A11="",N(I11)=0),"",L11/I11)
A12: =IF(고객사!$A$11="","",고객사!$A$11) | B12: =IF($A12="","",고객사!$B$11) | C12: =IF($A12="","",고객사!$G$11) | D12: =IF($A12="","",SUMIFS(일일계획실적!$U$5:$U$2004,일일계획실적!$B$5:$B$2004,$A12,일일계획실적!$A$5:$A$2004,">="&$F$3,일일계획실적!$A$5:$A$2004,"<"&$H$3)) | E12: =IF($A12="","",SUMIFS(일일계획실적!$F$5:$F$2004,일일계획실적!$B$5:$B$2004,$A12,일일계획실적!$A$5:$A$2004,">="&$F$3,일일계획실적!$A$5:$A$2004,"<"&$H$3)) | F12: =IF($A12="","",SUMIFS(일일계획실적!$G$5:$G$2004,일일계획실적!$B$5:$B$2004,$A12,일일계획실적!$A$5:$A$2004,">="&$F$3,일일계획실적!$A$5:$A$2004,"<"&$H$3)) | G12: =IF(OR($A12="",N(E12)=0),"",F12/E12) | H12: =IF($A12="","",SUMIFS(일일계획실적!$I$5:$I$2004,일일계획실적!$B$5:$B$2004,$A12,일일계획실적!$A$5:$A$2004,">="&$F$3,일일계획실적!$A$5:$A$2004,"<"&$H$3)) | I12: =IF($A12="","",SUMIFS(일일계획실적!$O$5:$O$2004,일일계획실적!$B$5:$B$2004,$A12,일일계획실적!$A$5:$A$2004,">="&$F$3,일일계획실적!$A$5:$A$2004,"<"&$H$3)) | J12: =IF($A12="","",SUMIFS(일일계획실적!$Q$5:$Q$2004,일일계획실적!$B$5:$B$2004,$A12,일일계획실적!$A$5:$A$2004,">="&$F$3,일일계획실적!$A$5:$A$2004,"<"&$H$3)) | K12: =IF($A12="","",SUMIFS(일일계획실적!$L$5:$L$2004,일일계획실적!$B$5:$B$2004,$A12,일일계획실적!$A$5:$A$2004,">="&$F$3,일일계획실적!$A$5:$A$2004,"<"&$H$3)) | L12: =IF($A12="","",I12-J12-K12) | M12: =IF(OR($A12="",N(I12)=0),"",L12/I12)
A13: =IF(고객사!$A$12="","",고객사!$A$12) | B13: =IF($A13="","",고객사!$B$12) | C13: =IF($A13="","",고객사!$G$12) | D13: =IF($A13="","",SUMIFS(일일계획실적!$U$5:$U$2004,일일계획실적!$B$5:$B$2004,$A13,일일계획실적!$A$5:$A$2004,">="&$F$3,일일계획실적!$A$5:$A$2004,"<"&$H$3)) | E13: =IF($A13="","",SUMIFS(일일계획실적!$F$5:$F$2004,일일계획실적!$B$5:$B$2004,$A13,일일계획실적!$A$5:$A$2004,">="&$F$3,일일계획실적!$A$5:$A$2004,"<"&$H$3)) | F13: =IF($A13="","",SUMIFS(일일계획실적!$G$5:$G$2004,일일계획실적!$B$5:$B$2004,$A13,일일계획실적!$A$5:$A$2004,">="&$F$3,일일계획실적!$A$5:$A$2004,"<"&$H$3)) | G13: =IF(OR($A13="",N(E13)=0),"",F13/E13) | H13: =IF($A13="","",SUMIFS(일일계획실적!$I$5:$I$2004,일일계획실적!$B$5:$B$2004,$A13,일일계획실적!$A$5:$A$2004,">="&$F$3,일일계획실적!$A$5:$A$2004,"<"&$H$3)) | I13: =IF($A13="","",SUMIFS(일일계획실적!$O$5:$O$2004,일일계획실적!$B$5:$B$2004,$A13,일일계획실적!$A$5:$A$2004,">="&$F$3,일일계획실적!$A$5:$A$2004,"<"&$H$3)) | J13: =IF($A13="","",SUMIFS(일일계획실적!$Q$5:$Q$2004,일일계획실적!$B$5:$B$2004,$A13,일일계획실적!$A$5:$A$2004,">="&$F$3,일일계획실적!$A$5:$A$2004,"<"&$H$3)) | K13: =IF($A13="","",SUMIFS(일일계획실적!$L$5:$L$2004,일일계획실적!$B$5:$B$2004,$A13,일일계획실적!$A$5:$A$2004,">="&$F$3,일일계획실적!$A$5:$A$2004,"<"&$H$3)) | L13: =IF($A13="","",I13-J13-K13) | M13: =IF(OR($A13="",N(I13)=0),"",L13/I13)
A14: =IF(고객사!$A$13="","",고객사!$A$13) | B14: =IF($A14="","",고객사!$B$13) | C14: =IF($A14="","",고객사!$G$13) | D14: =IF($A14="","",SUMIFS(일일계획실적!$U$5:$U$2004,일일계획실적!$B$5:$B$2004,$A14,일일계획실적!$A$5:$A$2004,">="&$F$3,일일계획실적!$A$5:$A$2004,"<"&$H$3)) | E14: =IF($A14="","",SUMIFS(일일계획실적!$F$5:$F$2004,일일계획실적!$B$5:$B$2004,$A14,일일계획실적!$A$5:$A$2004,">="&$F$3,일일계획실적!$A$5:$A$2004,"<"&$H$3)) | F14: =IF($A14="","",SUMIFS(일일계획실적!$G$5:$G$2004,일일계획실적!$B$5:$B$2004,$A14,일일계획실적!$A$5:$A$2004,">="&$F$3,일일계획실적!$A$5:$A$2004,"<"&$H$3)) | G14: =IF(OR($A14="",N(E14)=0),"",F14/E14) | H14: =IF($A14="","",SUMIFS(일일계획실적!$I$5:$I$2004,일일계획실적!$B$5:$B$2004,$A14,일일계획실적!$A$5:$A$2004,">="&$F$3,일일계획실적!$A$5:$A$2004,"<"&$H$3)) | I14: =IF($A14="","",SUMIFS(일일계획실적!$O$5:$O$2004,일일계획실적!$B$5:$B$2004,$A14,일일계획실적!$A$5:$A$2004,">="&$F$3,일일계획실적!$A$5:$A$2004,"<"&$H$3)) | J14: =IF($A14="","",SUMIFS(일일계획실적!$Q$5:$Q$2004,일일계획실적!$B$5:$B$2004,$A14,일일계획실적!$A$5:$A$2004,">="&$F$3,일일계획실적!$A$5:$A$2004,"<"&$H$3)) | K14: =IF($A14="","",SUMIFS(일일계획실적!$L$5:$L$2004,일일계획실적!$B$5:$B$2004,$A14,일일계획실적!$A$5:$A$2004,">="&$F$3,일일계획실적!$A$5:$A$2004,"<"&$H$3)) | L14: =IF($A14="","",I14-J14-K14) | M14: =IF(OR($A14="",N(I14)=0),"",L14/I14)
A15: =IF(고객사!$A$14="","",고객사!$A$14) | B15: =IF($A15="","",고객사!$B$14) | C15: =IF($A15="","",고객사!$G$14) | D15: =IF($A15="","",SUMIFS(일일계획실적!$U$5:$U$2004,일일계획실적!$B$5:$B$2004,$A15,일일계획실적!$A$5:$A$2004,">="&$F$3,일일계획실적!$A$5:$A$2004,"<"&$H$3)) | E15: =IF($A15="","",SUMIFS(일일계획실적!$F$5:$F$2004,일일계획실적!$B$5:$B$2004,$A15,일일계획실적!$A$5:$A$2004,">="&$F$3,일일계획실적!$A$5:$A$2004,"<"&$H$3)) | F15: =IF($A15="","",SUMIFS(일일계획실적!$G$5:$G$2004,일일계획실적!$B$5:$B$2004,$A15,일일계획실적!$A$5:$A$2004,">="&$F$3,일일계획실적!$A$5:$A$2004,"<"&$H$3)) | G15: =IF(OR($A15="",N(E15)=0),"",F15/E15) | H15: =IF($A15="","",SUMIFS(일일계획실적!$I$5:$I$2004,일일계획실적!$B$5:$B$2004,$A15,일일계획실적!$A$5:$A$2004,">="&$F$3,일일계획실적!$A$5:$A$2004,"<"&$H$3)) | I15: =IF($A15="","",SUMIFS(일일계획실적!$O$5:$O$2004,일일계획실적!$B$5:$B$2004,$A15,일일계획실적!$A$5:$A$2004,">="&$F$3,일일계획실적!$A$5:$A$2004,"<"&$H$3)) | J15: =IF($A15="","",SUMIFS(일일계획실적!$Q$5:$Q$2004,일일계획실적!$B$5:$B$2004,$A15,일일계획실적!$A$5:$A$2004,">="&$F$3,일일계획실적!$A$5:$A$2004,"<"&$H$3)) | K15: =IF($A15="","",SUMIFS(일일계획실적!$L$5:$L$2004,일일계획실적!$B$5:$B$2004,$A15,일일계획실적!$A$5:$A$2004,">="&$F$3,일일계획실적!$A$5:$A$2004,"<"&$H$3)) | L15: =IF($A15="","",I15-J15-K15) | M15: =IF(OR($A15="",N(I15)=0),"",L15/I15)
A16: =IF(고객사!$A$15="","",고객사!$A$15) | B16: =IF($A16="","",고객사!$B$15) | C16: =IF($A16="","",고객사!$G$15) | D16: =IF($A16="","",SUMIFS(일일계획실적!$U$5:$U$2004,일일계획실적!$B$5:$B$2004,$A16,일일계획실적!$A$5:$A$2004,">="&$F$3,일일계획실적!$A$5:$A$2004,"<"&$H$3)) | E16: =IF($A16="","",SUMIFS(일일계획실적!$F$5:$F$2004,일일계획실적!$B$5:$B$2004,$A16,일일계획실적!$A$5:$A$2004,">="&$F$3,일일계획실적!$A$5:$A$2004,"<"&$H$3)) | F16: =IF($A16="","",SUMIFS(일일계획실적!$G$5:$G$2004,일일계획실적!$B$5:$B$2004,$A16,일일계획실적!$A$5:$A$2004,">="&$F$3,일일계획실적!$A$5:$A$2004,"<"&$H$3)) | G16: =IF(OR($A16="",N(E16)=0),"",F16/E16) | H16: =IF($A16="","",SUMIFS(일일계획실적!$I$5:$I$2004,일일계획실적!$B$5:$B$2004,$A16,일일계획실적!$A$5:$A$2004,">="&$F$3,일일계획실적!$A$5:$A$2004,"<"&$H$3)) | I16: =IF($A16="","",SUMIFS(일일계획실적!$O$5:$O$2004,일일계획실적!$B$5:$B$2004,$A16,일일계획실적!$A$5:$A$2004,">="&$F$3,일일계획실적!$A$5:$A$2004,"<"&$H$3)) | J16: =IF($A16="","",SUMIFS(일일계획실적!$Q$5:$Q$2004,일일계획실적!$B$5:$B$2004,$A16,일일계획실적!$A$5:$A$2004,">="&$F$3,일일계획실적!$A$5:$A$2004,"<"&$H$3)) | K16: =IF($A16="","",SUMIFS(일일계획실적!$L$5:$L$2004,일일계획실적!$B$5:$B$2004,$A16,일일계획실적!$A$5:$A$2004,">="&$F$3,일일계획실적!$A$5:$A$2004,"<"&$H$3)) | L16: =IF($A16="","",I16-J16-K16) | M16: =IF(OR($A16="",N(I16)=0),"",L16/I16)
A17: =IF(고객사!$A$16="","",고객사!$A$16) | B17: =IF($A17="","",고객사!$B$16) | C17: =IF($A17="","",고객사!$G$16) | D17: =IF($A17="","",SUMIFS(일일계획실적!$U$5:$U$2004,일일계획실적!$B$5:$B$2004,$A17,일일계획실적!$A$5:$A$2004,">="&$F$3,일일계획실적!$A$5:$A$2004,"<"&$H$3)) | E17: =IF($A17="","",SUMIFS(일일계획실적!$F$5:$F$2004,일일계획실적!$B$5:$B$2004,$A17,일일계획실적!$A$5:$A$2004,">="&$F$3,일일계획실적!$A$5:$A$2004,"<"&$H$3)) | F17: =IF($A17="","",SUMIFS(일일계획실적!$G$5:$G$2004,일일계획실적!$B$5:$B$2004,$A17,일일계획실적!$A$5:$A$2004,">="&$F$3,일일계획실적!$A$5:$A$2004,"<"&$H$3)) | G17: =IF(OR($A17="",N(E17)=0),"",F17/E17) | H17: =IF($A17="","",SUMIFS(일일계획실적!$I$5:$I$2004,일일계획실적!$B$5:$B$2004,$A17,일일계획실적!$A$5:$A$2004,">="&$F$3,일일계획실적!$A$5:$A$2004,"<"&$H$3)) | I17: =IF($A17="","",SUMIFS(일일계획실적!$O$5:$O$2004,일일계획실적!$B$5:$B$2004,$A17,일일계획실적!$A$5:$A$2004,">="&$F$3,일일계획실적!$A$5:$A$2004,"<"&$H$3)) | J17: =IF($A17="","",SUMIFS(일일계획실적!$Q$5:$Q$2004,일일계획실적!$B$5:$B$2004,$A17,일일계획실적!$A$5:$A$2004,">="&$F$3,일일계획실적!$A$5:$A$2004,"<"&$H$3)) | K17: =IF($A17="","",SUMIFS(일일계획실적!$L$5:$L$2004,일일계획실적!$B$5:$B$2004,$A17,일일계획실적!$A$5:$A$2004,">="&$F$3,일일계획실적!$A$5:$A$2004,"<"&$H$3)) | L17: =IF($A17="","",I17-J17-K17) | M17: =IF(OR($A17="",N(I17)=0),"",L17/I17)
A18: =IF(고객사!$A$17="","",고객사!$A$17) | B18: =IF($A18="","",고객사!$B$17) | C18: =IF($A18="","",고객사!$G$17) | D18: =IF($A18="","",SUMIFS(일일계획실적!$U$5:$U$2004,일일계획실적!$B$5:$B$2004,$A18,일일계획실적!$A$5:$A$2004,">="&$F$3,일일계획실적!$A$5:$A$2004,"<"&$H$3)) | E18: =IF($A18="","",SUMIFS(일일계획실적!$F$5:$F$2004,일일계획실적!$B$5:$B$2004,$A18,일일계획실적!$A$5:$A$2004,">="&$F$3,일일계획실적!$A$5:$A$2004,"<"&$H$3)) | F18: =IF($A18="","",SUMIFS(일일계획실적!$G$5:$G$2004,일일계획실적!$B$5:$B$2004,$A18,일일계획실적!$A$5:$A$2004,">="&$F$3,일일계획실적!$A$5:$A$2004,"<"&$H$3)) | G18: =IF(OR($A18="",N(E18)=0),"",F18/E18) | H18: =IF($A18="","",SUMIFS(일일계획실적!$I$5:$I$2004,일일계획실적!$B$5:$B$2004,$A18,일일계획실적!$A$5:$A$2004,">="&$F$3,일일계획실적!$A$5:$A$2004,"<"&$H$3)) | I18: =IF($A18="","",SUMIFS(일일계획실적!$O$5:$O$2004,일일계획실적!$B$5:$B$2004,$A18,일일계획실적!$A$5:$A$2004,">="&$F$3,일일계획실적!$A$5:$A$2004,"<"&$H$3)) | J18: =IF($A18="","",SUMIFS(일일계획실적!$Q$5:$Q$2004,일일계획실적!$B$5:$B$2004,$A18,일일계획실적!$A$5:$A$2004,">="&$F$3,일일계획실적!$A$5:$A$2004,"<"&$H$3)) | K18: =IF($A18="","",SUMIFS(일일계획실적!$L$5:$L$2004,일일계획실적!$B$5:$B$2004,$A18,일일계획실적!$A$5:$A$2004,">="&$F$3,일일계획실적!$A$5:$A$2004,"<"&$H$3)) | L18: =IF($A18="","",I18-J18-K18) | M18: =IF(OR($A18="",N(I18)=0),"",L18/I18)
A19: =IF(고객사!$A$18="","",고객사!$A$18) | B19: =IF($A19="","",고객사!$B$18) | C19: =IF($A19="","",고객사!$G$18) | D19: =IF($A19="","",SUMIFS(일일계획실적!$U$5:$U$2004,일일계획실적!$B$5:$B$2004,$A19,일일계획실적!$A$5:$A$2004,">="&$F$3,일일계획실적!$A$5:$A$2004,"<"&$H$3)) | E19: =IF($A19="","",SUMIFS(일일계획실적!$F$5:$F$2004,일일계획실적!$B$5:$B$2004,$A19,일일계획실적!$A$5:$A$2004,">="&$F$3,일일계획실적!$A$5:$A$2004,"<"&$H$3)) | F19: =IF($A19="","",SUMIFS(일일계획실적!$G$5:$G$2004,일일계획실적!$B$5:$B$2004,$A19,일일계획실적!$A$5:$A$2004,">="&$F$3,일일계획실적!$A$5:$A$2004,"<"&$H$3)) | G19: =IF(OR($A19="",N(E19)=0),"",F19/E19) | H19: =IF($A19="","",SUMIFS(일일계획실적!$I$5:$I$2004,일일계획실적!$B$5:$B$2004,$A19,일일계획실적!$A$5:$A$2004,">="&$F$3,일일계획실적!$A$5:$A$2004,"<"&$H$3)) | I19: =IF($A19="","",SUMIFS(일일계획실적!$O$5:$O$2004,일일계획실적!$B$5:$B$2004,$A19,일일계획실적!$A$5:$A$2004,">="&$F$3,일일계획실적!$A$5:$A$2004,"<"&$H$3)) | J19: =IF($A19="","",SUMIFS(일일계획실적!$Q$5:$Q$2004,일일계획실적!$B$5:$B$2004,$A19,일일계획실적!$A$5:$A$2004,">="&$F$3,일일계획실적!$A$5:$A$2004,"<"&$H$3)) | K19: =IF($A19="","",SUMIFS(일일계획실적!$L$5:$L$2004,일일계획실적!$B$5:$B$2004,$A19,일일계획실적!$A$5:$A$2004,">="&$F$3,일일계획실적!$A$5:$A$2004,"<"&$H$3)) | L19: =IF($A19="","",I19-J19-K19) | M19: =IF(OR($A19="",N(I19)=0),"",L19/I19)
A20: =IF(고객사!$A$19="","",고객사!$A$19) | B20: =IF($A20="","",고객사!$B$19) | C20: =IF($A20="","",고객사!$G$19) | D20: =IF($A20="","",SUMIFS(일일계획실적!$U$5:$U$2004,일일계획실적!$B$5:$B$2004,$A20,일일계획실적!$A$5:$A$2004,">="&$F$3,일일계획실적!$A$5:$A$2004,"<"&$H$3)) | E20: =IF($A20="","",SUMIFS(일일계획실적!$F$5:$F$2004,일일계획실적!$B$5:$B$2004,$A20,일일계획실적!$A$5:$A$2004,">="&$F$3,일일계획실적!$A$5:$A$2004,"<"&$H$3)) | F20: =IF($A20="","",SUMIFS(일일계획실적!$G$5:$G$2004,일일계획실적!$B$5:$B$2004,$A20,일일계획실적!$A$5:$A$2004,">="&$F$3,일일계획실적!$A$5:$A$2004,"<"&$H$3)) | G20: =IF(OR($A20="",N(E20)=0),"",F20/E20) | H20: =IF($A20="","",SUMIFS(일일계획실적!$I$5:$I$2004,일일계획실적!$B$5:$B$2004,$A20,일일계획실적!$A$5:$A$2004,">="&$F$3,일일계획실적!$A$5:$A$2004,"<"&$H$3)) | I20: =IF($A20="","",SUMIFS(일일계획실적!$O$5:$O$2004,일일계획실적!$B$5:$B$2004,$A20,일일계획실적!$A$5:$A$2004,">="&$F$3,일일계획실적!$A$5:$A$2004,"<"&$H$3)) | J20: =IF($A20="","",SUMIFS(일일계획실적!$Q$5:$Q$2004,일일계획실적!$B$5:$B$2004,$A20,일일계획실적!$A$5:$A$2004,">="&$F$3,일일계획실적!$A$5:$A$2004,"<"&$H$3)) | K20: =IF($A20="","",SUMIFS(일일계획실적!$L$5:$L$2004,일일계획실적!$B$5:$B$2004,$A20,일일계획실적!$A$5:$A$2004,">="&$F$3,일일계획실적!$A$5:$A$2004,"<"&$H$3)) | L20: =IF($A20="","",I20-J20-K20) | M20: =IF(OR($A20="",N(I20)=0),"",L20/I20)
A21: =IF(고객사!$A$20="","",고객사!$A$20) | B21: =IF($A21="","",고객사!$B$20) | C21: =IF($A21="","",고객사!$G$20) | D21: =IF($A21="","",SUMIFS(일일계획실적!$U$5:$U$2004,일일계획실적!$B$5:$B$2004,$A21,일일계획실적!$A$5:$A$2004,">="&$F$3,일일계획실적!$A$5:$A$2004,"<"&$H$3)) | E21: =IF($A21="","",SUMIFS(일일계획실적!$F$5:$F$2004,일일계획실적!$B$5:$B$2004,$A21,일일계획실적!$A$5:$A$2004,">="&$F$3,일일계획실적!$A$5:$A$2004,"<"&$H$3)) | F21: =IF($A21="","",SUMIFS(일일계획실적!$G$5:$G$2004,일일계획실적!$B$5:$B$2004,$A21,일일계획실적!$A$5:$A$2004,">="&$F$3,일일계획실적!$A$5:$A$2004,"<"&$H$3)) | G21: =IF(OR($A21="",N(E21)=0),"",F21/E21) | H21: =IF($A21="","",SUMIFS(일일계획실적!$I$5:$I$2004,일일계획실적!$B$5:$B$2004,$A21,일일계획실적!$A$5:$A$2004,">="&$F$3,일일계획실적!$A$5:$A$2004,"<"&$H$3)) | I21: =IF($A21="","",SUMIFS(일일계획실적!$O$5:$O$2004,일일계획실적!$B$5:$B$2004,$A21,일일계획실적!$A$5:$A$2004,">="&$F$3,일일계획실적!$A$5:$A$2004,"<"&$H$3)) | J21: =IF($A21="","",SUMIFS(일일계획실적!$Q$5:$Q$2004,일일계획실적!$B$5:$B$2004,$A21,일일계획실적!$A$5:$A$2004,">="&$F$3,일일계획실적!$A$5:$A$2004,"<"&$H$3)) | K21: =IF($A21="","",SUMIFS(일일계획실적!$L$5:$L$2004,일일계획실적!$B$5:$B$2004,$A21,일일계획실적!$A$5:$A$2004,">="&$F$3,일일계획실적!$A$5:$A$2004,"<"&$H$3)) | L21: =IF($A21="","",I21-J21-K21) | M21: =IF(OR($A21="",N(I21)=0),"",L21/I21)
A22: =IF(고객사!$A$21="","",고객사!$A$21) | B22: =IF($A22="","",고객사!$B$21) | C22: =IF($A22="","",고객사!$G$21) | D22: =IF($A22="","",SUMIFS(일일계획실적!$U$5:$U$2004,일일계획실적!$B$5:$B$2004,$A22,일일계획실적!$A$5:$A$2004,">="&$F$3,일일계획실적!$A$5:$A$2004,"<"&$H$3)) | E22: =IF($A22="","",SUMIFS(일일계획실적!$F$5:$F$2004,일일계획실적!$B$5:$B$2004,$A22,일일계획실적!$A$5:$A$2004,">="&$F$3,일일계획실적!$A$5:$A$2004,"<"&$H$3)) | F22: =IF($A22="","",SUMIFS(일일계획실적!$G$5:$G$2004,일일계획실적!$B$5:$B$2004,$A22,일일계획실적!$A$5:$A$2004,">="&$F$3,일일계획실적!$A$5:$A$2004,"<"&$H$3)) | G22: =IF(OR($A22="",N(E22)=0),"",F22/E22) | H22: =IF($A22="","",SUMIFS(일일계획실적!$I$5:$I$2004,일일계획실적!$B$5:$B$2004,$A22,일일계획실적!$A$5:$A$2004,">="&$F$3,일일계획실적!$A$5:$A$2004,"<"&$H$3)) | I22: =IF($A22="","",SUMIFS(일일계획실적!$O$5:$O$2004,일일계획실적!$B$5:$B$2004,$A22,일일계획실적!$A$5:$A$2004,">="&$F$3,일일계획실적!$A$5:$A$2004,"<"&$H$3)) | J22: =IF($A22="","",SUMIFS(일일계획실적!$Q$5:$Q$2004,일일계획실적!$B$5:$B$2004,$A22,일일계획실적!$A$5:$A$2004,">="&$F$3,일일계획실적!$A$5:$A$2004,"<"&$H$3)) | K22: =IF($A22="","",SUMIFS(일일계획실적!$L$5:$L$2004,일일계획실적!$B$5:$B$2004,$A22,일일계획실적!$A$5:$A$2004,">="&$F$3,일일계획실적!$A$5:$A$2004,"<"&$H$3)) | L22: =IF($A22="","",I22-J22-K22) | M22: =IF(OR($A22="",N(I22)=0),"",L22/I22)
A23: =IF(고객사!$A$22="","",고객사!$A$22) | B23: =IF($A23="","",고객사!$B$22) | C23: =IF($A23="","",고객사!$G$22) | D23: =IF($A23="","",SUMIFS(일일계획실적!$U$5:$U$2004,일일계획실적!$B$5:$B$2004,$A23,일일계획실적!$A$5:$A$2004,">="&$F$3,일일계획실적!$A$5:$A$2004,"<"&$H$3)) | E23: =IF($A23="","",SUMIFS(일일계획실적!$F$5:$F$2004,일일계획실적!$B$5:$B$2004,$A23,일일계획실적!$A$5:$A$2004,">="&$F$3,일일계획실적!$A$5:$A$2004,"<"&$H$3)) | F23: =IF($A23="","",SUMIFS(일일계획실적!$G$5:$G$2004,일일계획실적!$B$5:$B$2004,$A23,일일계획실적!$A$5:$A$2004,">="&$F$3,일일계획실적!$A$5:$A$2004,"<"&$H$3)) | G23: =IF(OR($A23="",N(E23)=0),"",F23/E23) | H23: =IF($A23="","",SUMIFS(일일계획실적!$I$5:$I$2004,일일계획실적!$B$5:$B$2004,$A23,일일계획실적!$A$5:$A$2004,">="&$F$3,일일계획실적!$A$5:$A$2004,"<"&$H$3)) | I23: =IF($A23="","",SUMIFS(일일계획실적!$O$5:$O$2004,일일계획실적!$B$5:$B$2004,$A23,일일계획실적!$A$5:$A$2004,">="&$F$3,일일계획실적!$A$5:$A$2004,"<"&$H$3)) | J23: =IF($A23="","",SUMIFS(일일계획실적!$Q$5:$Q$2004,일일계획실적!$B$5:$B$2004,$A23,일일계획실적!$A$5:$A$2004,">="&$F$3,일일계획실적!$A$5:$A$2004,"<"&$H$3)) | K23: =IF($A23="","",SUMIFS(일일계획실적!$L$5:$L$2004,일일계획실적!$B$5:$B$2004,$A23,일일계획실적!$A$5:$A$2004,">="&$F$3,일일계획실적!$A$5:$A$2004,"<"&$H$3)) | L23: =IF($A23="","",I23-J23-K23) | M23: =IF(OR($A23="",N(I23)=0),"",L23/I23)
A24: =IF(고객사!$A$23="","",고객사!$A$23) | B24: =IF($A24="","",고객사!$B$23) | C24: =IF($A24="","",고객사!$G$23) | D24: =IF($A24="","",SUMIFS(일일계획실적!$U$5:$U$2004,일일계획실적!$B$5:$B$2004,$A24,일일계획실적!$A$5:$A$2004,">="&$F$3,일일계획실적!$A$5:$A$2004,"<"&$H$3)) | E24: =IF($A24="","",SUMIFS(일일계획실적!$F$5:$F$2004,일일계획실적!$B$5:$B$2004,$A24,일일계획실적!$A$5:$A$2004,">="&$F$3,일일계획실적!$A$5:$A$2004,"<"&$H$3)) | F24: =IF($A24="","",SUMIFS(일일계획실적!$G$5:$G$2004,일일계획실적!$B$5:$B$2004,$A24,일일계획실적!$A$5:$A$2004,">="&$F$3,일일계획실적!$A$5:$A$2004,"<"&$H$3)) | G24: =IF(OR($A24="",N(E24)=0),"",F24/E24) | H24: =IF($A24="","",SUMIFS(일일계획실적!$I$5:$I$2004,일일계획실적!$B$5:$B$2004,$A24,일일계획실적!$A$5:$A$2004,">="&$F$3,일일계획실적!$A$5:$A$2004,"<"&$H$3)) | I24: =IF($A24="","",SUMIFS(일일계획실적!$O$5:$O$2004,일일계획실적!$B$5:$B$2004,$A24,일일계획실적!$A$5:$A$2004,">="&$F$3,일일계획실적!$A$5:$A$2004,"<"&$H$3)) | J24: =IF($A24="","",SUMIFS(일일계획실적!$Q$5:$Q$2004,일일계획실적!$B$5:$B$2004,$A24,일일계획실적!$A$5:$A$2004,">="&$F$3,일일계획실적!$A$5:$A$2004,"<"&$H$3)) | K24: =IF($A24="","",SUMIFS(일일계획실적!$L$5:$L$2004,일일계획실적!$B$5:$B$2004,$A24,일일계획실적!$A$5:$A$2004,">="&$F$3,일일계획실적!$A$5:$A$2004,"<"&$H$3)) | L24: =IF($A24="","",I24-J24-K24) | M24: =IF(OR($A24="",N(I24)=0),"",L24/I24)
A25: =IF(고객사!$A$24="","",고객사!$A$24) | B25: =IF($A25="","",고객사!$B$24) | C25: =IF($A25="","",고객사!$G$24) | D25: =IF($A25="","",SUMIFS(일일계획실적!$U$5:$U$2004,일일계획실적!$B$5:$B$2004,$A25,일일계획실적!$A$5:$A$2004,">="&$F$3,일일계획실적!$A$5:$A$2004,"<"&$H$3)) | E25: =IF($A25="","",SUMIFS(일일계획실적!$F$5:$F$2004,일일계획실적!$B$5:$B$2004,$A25,일일계획실적!$A$5:$A$2004,">="&$F$3,일일계획실적!$A$5:$A$2004,"<"&$H$3)) | F25: =IF($A25="","",SUMIFS(일일계획실적!$G$5:$G$2004,일일계획실적!$B$5:$B$2004,$A25,일일계획실적!$A$5:$A$2004,">="&$F$3,일일계획실적!$A$5:$A$2004,"<"&$H$3)) | G25: =IF(OR($A25="",N(E25)=0),"",F25/E25) | H25: =IF($A25="","",SUMIFS(일일계획실적!$I$5:$I$2004,일일계획실적!$B$5:$B$2004,$A25,일일계획실적!$A$5:$A$2004,">="&$F$3,일일계획실적!$A$5:$A$2004,"<"&$H$3)) | I25: =IF($A25="","",SUMIFS(일일계획실적!$O$5:$O$2004,일일계획실적!$B$5:$B$2004,$A25,일일계획실적!$A$5:$A$2004,">="&$F$3,일일계획실적!$A$5:$A$2004,"<"&$H$3)) | J25: =IF($A25="","",SUMIFS(일일계획실적!$Q$5:$Q$2004,일일계획실적!$B$5:$B$2004,$A25,일일계획실적!$A$5:$A$2004,">="&$F$3,일일계획실적!$A$5:$A$2004,"<"&$H$3)) | K25: =IF($A25="","",SUMIFS(일일계획실적!$L$5:$L$2004,일일계획실적!$B$5:$B$2004,$A25,일일계획실적!$A$5:$A$2004,">="&$F$3,일일계획실적!$A$5:$A$2004,"<"&$H$3)) | L25: =IF($A25="","",I25-J25-K25) | M25: =IF(OR($A25="",N(I25)=0),"",L25/I25)
A26: =IF(고객사!$A$25="","",고객사!$A$25) | B26: =IF($A26="","",고객사!$B$25) | C26: =IF($A26="","",고객사!$G$25) | D26: =IF($A26="","",SUMIFS(일일계획실적!$U$5:$U$2004,일일계획실적!$B$5:$B$2004,$A26,일일계획실적!$A$5:$A$2004,">="&$F$3,일일계획실적!$A$5:$A$2004,"<"&$H$3)) | E26: =IF($A26="","",SUMIFS(일일계획실적!$F$5:$F$2004,일일계획실적!$B$5:$B$2004,$A26,일일계획실적!$A$5:$A$2004,">="&$F$3,일일계획실적!$A$5:$A$2004,"<"&$H$3)) | F26: =IF($A26="","",SUMIFS(일일계획실적!$G$5:$G$2004,일일계획실적!$B$5:$B$2004,$A26,일일계획실적!$A$5:$A$2004,">="&$F$3,일일계획실적!$A$5:$A$2004,"<"&$H$3)) | G26: =IF(OR($A26="",N(E26)=0),"",F26/E26) | H26: =IF($A26="","",SUMIFS(일일계획실적!$I$5:$I$2004,일일계획실적!$B$5:$B$2004,$A26,일일계획실적!$A$5:$A$2004,">="&$F$3,일일계획실적!$A$5:$A$2004,"<"&$H$3)) | I26: =IF($A26="","",SUMIFS(일일계획실적!$O$5:$O$2004,일일계획실적!$B$5:$B$2004,$A26,일일계획실적!$A$5:$A$2004,">="&$F$3,일일계획실적!$A$5:$A$2004,"<"&$H$3)) | J26: =IF($A26="","",SUMIFS(일일계획실적!$Q$5:$Q$2004,일일계획실적!$B$5:$B$2004,$A26,일일계획실적!$A$5:$A$2004,">="&$F$3,일일계획실적!$A$5:$A$2004,"<"&$H$3)) | K26: =IF($A26="","",SUMIFS(일일계획실적!$L$5:$L$2004,일일계획실적!$B$5:$B$2004,$A26,일일계획실적!$A$5:$A$2004,">="&$F$3,일일계획실적!$A$5:$A$2004,"<"&$H$3)) | L26: =IF($A26="","",I26-J26-K26) | M26: =IF(OR($A26="",N(I26)=0),"",L26/I26)
A27: =IF(고객사!$A$26="","",고객사!$A$26) | B27: =IF($A27="","",고객사!$B$26) | C27: =IF($A27="","",고객사!$G$26) | D27: =IF($A27="","",SUMIFS(일일계획실적!$U$5:$U$2004,일일계획실적!$B$5:$B$2004,$A27,일일계획실적!$A$5:$A$2004,">="&$F$3,일일계획실적!$A$5:$A$2004,"<"&$H$3)) | E27: =IF($A27="","",SUMIFS(일일계획실적!$F$5:$F$2004,일일계획실적!$B$5:$B$2004,$A27,일일계획실적!$A$5:$A$2004,">="&$F$3,일일계획실적!$A$5:$A$2004,"<"&$H$3)) | F27: =IF($A27="","",SUMIFS(일일계획실적!$G$5:$G$2004,일일계획실적!$B$5:$B$2004,$A27,일일계획실적!$A$5:$A$2004,">="&$F$3,일일계획실적!$A$5:$A$2004,"<"&$H$3)) | G27: =IF(OR($A27="",N(E27)=0),"",F27/E27) | H27: =IF($A27="","",SUMIFS(일일계획실적!$I$5:$I$2004,일일계획실적!$B$5:$B$2004,$A27,일일계획실적!$A$5:$A$2004,">="&$F$3,일일계획실적!$A$5:$A$2004,"<"&$H$3)) | I27: =IF($A27="","",SUMIFS(일일계획실적!$O$5:$O$2004,일일계획실적!$B$5:$B$2004,$A27,일일계획실적!$A$5:$A$2004,">="&$F$3,일일계획실적!$A$5:$A$2004,"<"&$H$3)) | J27: =IF($A27="","",SUMIFS(일일계획실적!$Q$5:$Q$2004,일일계획실적!$B$5:$B$2004,$A27,일일계획실적!$A$5:$A$2004,">="&$F$3,일일계획실적!$A$5:$A$2004,"<"&$H$3)) | K27: =IF($A27="","",SUMIFS(일일계획실적!$L$5:$L$2004,일일계획실적!$B$5:$B$2004,$A27,일일계획실적!$A$5:$A$2004,">="&$F$3,일일계획실적!$A$5:$A$2004,"<"&$H$3)) | L27: =IF($A27="","",I27-J27-K27) | M27: =IF(OR($A27="",N(I27)=0),"",L27/I27)
A28: =IF(고객사!$A$27="","",고객사!$A$27) | B28: =IF($A28="","",고객사!$B$27) | C28: =IF($A28="","",고객사!$G$27) | D28: =IF($A28="","",SUMIFS(일일계획실적!$U$5:$U$2004,일일계획실적!$B$5:$B$2004,$A28,일일계획실적!$A$5:$A$2004,">="&$F$3,일일계획실적!$A$5:$A$2004,"<"&$H$3)) | E28: =IF($A28="","",SUMIFS(일일계획실적!$F$5:$F$2004,일일계획실적!$B$5:$B$2004,$A28,일일계획실적!$A$5:$A$2004,">="&$F$3,일일계획실적!$A$5:$A$2004,"<"&$H$3)) | F28: =IF($A28="","",SUMIFS(일일계획실적!$G$5:$G$2004,일일계획실적!$B$5:$B$2004,$A28,일일계획실적!$A$5:$A$2004,">="&$F$3,일일계획실적!$A$5:$A$2004,"<"&$H$3)) | G28: =IF(OR($A28="",N(E28)=0),"",F28/E28) | H28: =IF($A28="","",SUMIFS(일일계획실적!$I$5:$I$2004,일일계획실적!$B$5:$B$2004,$A28,일일계획실적!$A$5:$A$2004,">="&$F$3,일일계획실적!$A$5:$A$2004,"<"&$H$3)) | I28: =IF($A28="","",SUMIFS(일일계획실적!$O$5:$O$2004,일일계획실적!$B$5:$B$2004,$A28,일일계획실적!$A$5:$A$2004,">="&$F$3,일일계획실적!$A$5:$A$2004,"<"&$H$3)) | J28: =IF($A28="","",SUMIFS(일일계획실적!$Q$5:$Q$2004,일일계획실적!$B$5:$B$2004,$A28,일일계획실적!$A$5:$A$2004,">="&$F$3,일일계획실적!$A$5:$A$2004,"<"&$H$3)) | K28: =IF($A28="","",SUMIFS(일일계획실적!$L$5:$L$2004,일일계획실적!$B$5:$B$2004,$A28,일일계획실적!$A$5:$A$2004,">="&$F$3,일일계획실적!$A$5:$A$2004,"<"&$H$3)) | L28: =IF($A28="","",I28-J28-K28) | M28: =IF(OR($A28="",N(I28)=0),"",L28/I28)
A29: =IF(고객사!$A$28="","",고객사!$A$28) | B29: =IF($A29="","",고객사!$B$28) | C29: =IF($A29="","",고객사!$G$28) | D29: =IF($A29="","",SUMIFS(일일계획실적!$U$5:$U$2004,일일계획실적!$B$5:$B$2004,$A29,일일계획실적!$A$5:$A$2004,">="&$F$3,일일계획실적!$A$5:$A$2004,"<"&$H$3)) | E29: =IF($A29="","",SUMIFS(일일계획실적!$F$5:$F$2004,일일계획실적!$B$5:$B$2004,$A29,일일계획실적!$A$5:$A$2004,">="&$F$3,일일계획실적!$A$5:$A$2004,"<"&$H$3)) | F29: =IF($A29="","",SUMIFS(일일계획실적!$G$5:$G$2004,일일계획실적!$B$5:$B$2004,$A29,일일계획실적!$A$5:$A$2004,">="&$F$3,일일계획실적!$A$5:$A$2004,"<"&$H$3)) | G29: =IF(OR($A29="",N(E29)=0),"",F29/E29) | H29: =IF($A29="","",SUMIFS(일일계획실적!$I$5:$I$2004,일일계획실적!$B$5:$B$2004,$A29,일일계획실적!$A$5:$A$2004,">="&$F$3,일일계획실적!$A$5:$A$2004,"<"&$H$3)) | I29: =IF($A29="","",SUMIFS(일일계획실적!$O$5:$O$2004,일일계획실적!$B$5:$B$2004,$A29,일일계획실적!$A$5:$A$2004,">="&$F$3,일일계획실적!$A$5:$A$2004,"<"&$H$3)) | J29: =IF($A29="","",SUMIFS(일일계획실적!$Q$5:$Q$2004,일일계획실적!$B$5:$B$2004,$A29,일일계획실적!$A$5:$A$2004,">="&$F$3,일일계획실적!$A$5:$A$2004,"<"&$H$3)) | K29: =IF($A29="","",SUMIFS(일일계획실적!$L$5:$L$2004,일일계획실적!$B$5:$B$2004,$A29,일일계획실적!$A$5:$A$2004,">="&$F$3,일일계획실적!$A$5:$A$2004,"<"&$H$3)) | L29: =IF($A29="","",I29-J29-K29) | M29: =IF(OR($A29="",N(I29)=0),"",L29/I29)
A30: =IF(고객사!$A$29="","",고객사!$A$29) | B30: =IF($A30="","",고객사!$B$29) | C30: =IF($A30="","",고객사!$G$29) | D30: =IF($A30="","",SUMIFS(일일계획실적!$U$5:$U$2004,일일계획실적!$B$5:$B$2004,$A30,일일계획실적!$A$5:$A$2004,">="&$F$3,일일계획실적!$A$5:$A$2004,"<"&$H$3)) | E30: =IF($A30="","",SUMIFS(일일계획실적!$F$5:$F$2004,일일계획실적!$B$5:$B$2004,$A30,일일계획실적!$A$5:$A$2004,">="&$F$3,일일계획실적!$A$5:$A$2004,"<"&$H$3)) | F30: =IF($A30="","",SUMIFS(일일계획실적!$G$5:$G$2004,일일계획실적!$B$5:$B$2004,$A30,일일계획실적!$A$5:$A$2004,">="&$F$3,일일계획실적!$A$5:$A$2004,"<"&$H$3)) | G30: =IF(OR($A30="",N(E30)=0),"",F30/E30) | H30: =IF($A30="","",SUMIFS(일일계획실적!$I$5:$I$2004,일일계획실적!$B$5:$B$2004,$A30,일일계획실적!$A$5:$A$2004,">="&$F$3,일일계획실적!$A$5:$A$2004,"<"&$H$3)) | I30: =IF($A30="","",SUMIFS(일일계획실적!$O$5:$O$2004,일일계획실적!$B$5:$B$2004,$A30,일일계획실적!$A$5:$A$2004,">="&$F$3,일일계획실적!$A$5:$A$2004,"<"&$H$3)) | J30: =IF($A30="","",SUMIFS(일일계획실적!$Q$5:$Q$2004,일일계획실적!$B$5:$B$2004,$A30,일일계획실적!$A$5:$A$2004,">="&$F$3,일일계획실적!$A$5:$A$2004,"<"&$H$3)) | K30: =IF($A30="","",SUMIFS(일일계획실적!$L$5:$L$2004,일일계획실적!$B$5:$B$2004,$A30,일일계획실적!$A$5:$A$2004,">="&$F$3,일일계획실적!$A$5:$A$2004,"<"&$H$3)) | L30: =IF($A30="","",I30-J30-K30) | M30: =IF(OR($A30="",N(I30)=0),"",L30/I30)
